Workbook

Sheet Dashboard
A1: AION 2 - Kina Mingguan: Dashboard
A4: 1. PLAY COUNT SAAT INI
A5: Conquest | B5: 50 | C5: Tier sekarang | D5: =SUMIFS(Setting!$E$30:$E$39,Setting!$A$30:$A$39,$A5,Setting!$C$30:$C$39,"<="&$B5,Setting!$D$30:$D$39,">="&$B5) -> 1 | E5: Play lagi sebelum tier turun | F5: =IF(SUMIFS(Setting!$D$30:$D$39,Setting!$A$30:$A$39,$A5,Setting!$C$30:$C$39,"<="&$B5,Setting!$D$30:$D$39,">="&$B5)>=999999,"tier terakhir",SUMIFS(Setting!$D$30:$D$39,Setting!$A$30:$A$39,$A5,Setting!$C$30:$C$39,"<="&$B5,Setting!$D$30:$D$39,">="&$B5)-$B5+1) -> 34 | G5: Tier berikutnya | H5: =IF(F5="tier terakhir","-",SUMIFS(Setting!$E$30:$E$39,Setting!$A$30:$A$39,$A5,Setting!$C$30:$C$39,"<="&($B5+F5),Setting!$D$30:$D$39,">="&($B5+F5))) -> 0.8
A6: Transcend | B6: 5 | C6: Tier sekarang | D6: =SUMIFS(Setting!$E$30:$E$39,Setting!$A$30:$A$39,$A6,Setting!$C$30:$C$39,"<="&$B6,Setting!$D$30:$D$39,">="&$B6) -> 1 | E6: Play lagi sebelum tier turun | F6: =IF(SUMIFS(Setting!$D$30:$D$39,Setting!$A$30:$A$39,$A6,Setting!$C$30:$C$39,"<="&$B6,Setting!$D$30:$D$39,">="&$B6)>=999999,"tier terakhir",SUMIFS(Setting!$D$30:$D$39,Setting!$A$30:$A$39,$A6,Setting!$C$30:$C$39,"<="&$B6,Setting!$D$30:$D$39,">="&$B6)-$B6+1) -> 51 | G6: Tier berikutnya | H6: =IF(F6="tier terakhir","-",SUMIFS(Setting!$E$30:$E$39,Setting!$A$30:$A$39,$A6,Setting!$C$30:$C$39,"<="&($B6+F6),Setting!$D$30:$D$39,">="&($B6+F6))) -> 0.8
A8: 2. REKOMENDASI
A9: {=IFERROR("MAIN SEKARANG: "&INDEX($A$15:$A$22,MATCH(1,$H$15:$H$22,0))&" > "&INDEX($F$15:$F$22,MATCH(1,$H$15:$H$22,0))&" (sekitar "&FIXED(INDEX($G$15:$G$22,MATCH(1,$H$15:$H$22,0)),0)&" kina/cube)","Tidak ada karakter dengan Odyle 'Tersedia' (atau tidak ada mode yang sesuai GS).")} -> MAIN SEKARANG: Roxarika > S1 (sekitar 300,000 kina/cube)
A10: {=IFERROR("BERIKUTNYA: "&INDEX($A$15:$A$22,MATCH(2,$H$15:$H$22,0))&" > "&INDEX($F$15:$F$22,MATCH(2,$H$15:$H$22,0))&" (sekitar "&FIXED(INDEX($G$15:$G$22,MATCH(2,$H$15:$H$22,0)),0)&" kina/cube)","")} -> BERIKUTNYA: Crosley > T2 (sekitar 300,000 kina/cube)
A11: {=IFERROR("NAIKKAN GS: "&INDEX($A$15:$A$22,MATCH(1,$M$15:$M$22,0))&" > "&INDEX($I$15:$I$22,MATCH(1,$M$15:$M$22,0))&" (kurang "&FIXED(INDEX($J$15:$J$22,MATCH(1,$M$15:$M$22,0)),0)&" GS, sekitar +"&FIXED(INDEX($K$15:$K$22,MATCH(1,$M$15:$M$22,0)),0)&" kina/minggu)","Tidak ada mode lebih bernilai yang bisa dibuka.")} -> NAIKKAN GS: Roxarika > S2 (1,900) (kurang 45 GS, sekitar +864,000 kina/minggu)
A13: 3. KARAKTER
A14: Karakter | B14: GS terbaru | C14: GS awal (sekali) | D14: Naik total | E14: Odyle | F14: Mode terbaik | G14: Kina / cube sekarang | H14: Urutan main | I14: Target tier (GS) | J14: Kurang GS | K14: Tambah kina / minggu | L14: Kina / minggu per 1 GS | M14: Prioritas naik GS | N14: Gear | O14: Saran
A15: ChromeT | B15: 2531 | C15: 2428 | D15: =IF(OR(A15="",B15=""),"",B15-C15) -> 103 | E15: Habis | F15: =IF(A15="","",Hitung!Y17) -> S4 | G15: =IF(A15="","",Hitung!Z17) -> 480000 | H15: =IF(A15="","",IF(Hitung!AA17<0,"-",Hitung!AB17)) -> - | I15: =IF(A15="","",IF(Hitung!AL17=0,"-",Hitung!AM17&" ("&FIXED(Hitung!AN17,0)&")")) -> - | J15: =IF(OR(A15="",Hitung!AL17=0),"",Hitung!AO17) | K15: =IF(OR(A15="",Hitung!AL17=0),"",Hitung!AQ17) | L15: =IF(OR(A15="",Hitung!AL17=0),"",Hitung!AK17) | M15: =IF(A15="","",IF(Hitung!AR17<0,"-",Hitung!AS17)) -> - | N15: =IF(A15="","",IF(Gear!W6=0,"Lengkap",Gear!W6&" item kurang (Acc "&Gear!U6&" / Gear "&Gear!V6&")")) -> 4 item kurang (Acc 1 / Gear 3) | O15: =IF(A15="","",IF(E15="Habis","Odyle habis: tunggu pulih",IF(H15=1,"MAIN SEKARANG",IF(ISNUMBER(H15),"Main urutan "&H15,"-")))&IF(M15=1," | PRIORITAS NAIK GS","")) -> Odyle habis: tunggu pulih
A16: Roxarika | B16: 1855 | C16: 1726 | D16: =IF(OR(A16="",B16=""),"",B16-C16) -> 129 | E16: Tersedia | F16: =IF(A16="","",Hitung!Y18) -> S1 | G16: =IF(A16="","",Hitung!Z18) -> 300000 | H16: =IF(A16="","",IF(Hitung!AA18<0,"-",Hitung!AB18)) -> 1 | I16: =IF(A16="","",IF(Hitung!AL18=0,"-",Hitung!AM18&" ("&FIXED(Hitung!AN18,0)&")")) -> S2 (1,900) | J16: =IF(OR(A16="",Hitung!AL18=0),"",Hitung!AO18) -> 45 | K16: =IF(OR(A16="",Hitung!AL18=0),"",Hitung!AQ18) -> 864000 | L16: =IF(OR(A16="",Hitung!AL18=0),"",Hitung!AK18) -> 19200 | M16: =IF(A16="","",IF(Hitung!AR18<0,"-",Hitung!AS18)) -> 1 | N16: =IF(A16="","",IF(Gear!W7=0,"Lengkap",Gear!W7&" item kurang (Acc "&Gear!U7&" / Gear "&Gear!V7&")")) -> 14 item kurang (Acc 6 / Gear 8) | O16: =IF(A16="","",IF(E16="Habis","Odyle habis: tunggu pulih",IF(H16=1,"MAIN SEKARANG",IF(ISNUMBER(H16),"Main urutan "&H16,"-")))&IF(M16=1," | PRIORITAS NAIK GS","")) -> MAIN SEKARANG | PRIORITAS NAIK GS
A17: Crosley | B17: 1595 | C17: 1569 | D17: =IF(OR(A17="",B17=""),"",B17-C17) -> 26 | E17: Tersedia | F17: =IF(A17="","",Hitung!Y19) -> T2 | G17: =IF(A17="","",Hitung!Z19) -> 300000 | H17: =IF(A17="","",IF(Hitung!AA19<0,"-",Hitung!AB19)) -> 2 | I17: =IF(A17="","",IF(Hitung!AL19=0,"-",Hitung!AM19&" ("&FIXED(Hitung!AN19,0)&")")) -> T3 (2,100) | J17: =IF(OR(A17="",Hitung!AL19=0),"",Hitung!AO19) -> 505 | K17: =IF(OR(A17="",Hitung!AL19=0),"",Hitung!AQ19) -> 2100000 | L17: =IF(OR(A17="",Hitung!AL19=0),"",Hitung!AK19) -> 4158.4158 | M17: =IF(A17="","",IF(Hitung!AR19<0,"-",Hitung!AS19)) -> 3 | N17: =IF(A17="","",IF(Gear!W8=0,"Lengkap",Gear!W8&" item kurang (Acc "&Gear!U8&" / Gear "&Gear!V8&")")) -> 14 item kurang (Acc 6 / Gear 8) | O17: =IF(A17="","",IF(E17="Habis","Odyle habis: tunggu pulih",IF(H17=1,"MAIN SEKARANG",IF(ISNUMBER(H17),"Main urutan "&H17,"-")))&IF(M17=1," | PRIORITAS NAIK GS","")) -> Main urutan 2
A18: Nathanael | B18: 1578 | C18: 1548 | D18: =IF(OR(A18="",B18=""),"",B18-C18) -> 30 | E18: Tersedia | F18: =IF(A18="","",Hitung!Y20) -> T2 | G18: =IF(A18="","",Hitung!Z20) -> 300000 | H18: =IF(A18="","",IF(Hitung!AA20<0,"-",Hitung!AB20)) -> 3 | I18: =IF(A18="","",IF(Hitung!AL20=0,"-",Hitung!AM20&" ("&FIXED(Hitung!AN20,0)&")")) -> T3 (2,100) | J18: =IF(OR(A18="",Hitung!AL20=0),"",Hitung!AO20) -> 522 | K18: =IF(OR(A18="",Hitung!AL20=0),"",Hitung!AQ20) -> 2100000 | L18: =IF(OR(A18="",Hitung!AL20=0),"",Hitung!AK20) -> 4022.9885 | M18: =IF(A18="","",IF(Hitung!AR20<0,"-",Hitung!AS20)) -> 5 | N18: =IF(A18="","",IF(Gear!W9=0,"Lengkap",Gear!W9&" item kurang (Acc "&Gear!U9&" / Gear "&Gear!V9&")")) -> 14 item kurang (Acc 6 / Gear 8) | O18: =IF(A18="","",IF(E18="Habis","Odyle habis: tunggu pulih",IF(H18=1,"MAIN SEKARANG",IF(ISNUMBER(H18),"Main urutan "&H18,"-")))&IF(M18=1," | PRIORITAS NAIK GS","")) -> Main urutan 3
A19: Cicero | B19: 1502 | C19: 1498 | D19: =IF(OR(A19="",B19=""),"",B19-C19) -> 4 | E19: Tersedia | F19: =IF(A19="","",Hitung!Y21) -> T2 | G19: =IF(A19="","",Hitung!Z21) -> 300000 | H19: =IF(A19="","",IF(Hitung!AA21<0,"-",Hitung!AB21)) -> 4 | I19: =IF(A19="","",IF(Hitung!AL21=0,"-",Hitung!AM21&" ("&FIXED(Hitung!AN21,0)&")")) -> T3 (2,100) | J19: =IF(OR(A19="",Hitung!AL21=0),"",Hitung!AO21) -> 598 | K19: =IF(OR(A19="",Hitung!AL21=0),"",Hitung!AQ21) -> 2100000 | L19: =IF(OR(A19="",Hitung!AL21=0),"",Hitung!AK21) -> 3511.7057 | M19: =IF(A19="","",IF(Hitung!AR21<0,"-",Hitung!AS21)) -> 7 | N19: =IF(A19="","",IF(Gear!W10=0,"Lengkap",Gear!W10&" item kurang (Acc "&Gear!U10&" / Gear "&Gear!V10&")")) -> 14 item kurang (Acc 6 / Gear 8) | O19: =IF(A19="","",IF(E19="Habis","Odyle habis: tunggu pulih",IF(H19=1,"MAIN SEKARANG",IF(ISNUMBER(H19),"Main urutan "&H19,"-")))&IF(M19=1," | PRIORITAS NAIK GS","")) -> Main urutan 4
A20: Seneca | B20: 1604 | C20: 1559 | D20: =IF(OR(A20="",B20=""),"",B20-C20) -> 45 | E20: Tersedia | F20: =IF(A20="","",Hitung!Y22) -> S1 | G20: =IF(A20="","",Hitung!Z22) -> 300000 | H20: =IF(A20="","",IF(Hitung!AA22<0,"-",Hitung!AB22)) -> 5 | I20: =IF(A20="","",IF(Hitung!AL22=0,"-",Hitung!AM22&" ("&FIXED(Hitung!AN22,0)&")")) -> T3 (2,100) | J20: =IF(OR(A20="",Hitung!AL22=0),"",Hitung!AO22) -> 496 | K20: =IF(OR(A20="",Hitung!AL22=0),"",Hitung!AQ22) -> 3540000 | L20: =IF(OR(A20="",Hitung!AL22=0),"",Hitung!AK22) -> 7137.0968 | M20: =IF(A20="","",IF(Hitung!AR22<0,"-",Hitung!AS22)) -> 2 | N20: =IF(A20="","",IF(Gear!W11=0,"Lengkap",Gear!W11&" item kurang (Acc "&Gear!U11&" / Gear "&Gear!V11&")")) -> 14 item kurang (Acc 6 / Gear 8) | O20: =IF(A20="","",IF(E20="Habis","Odyle habis: tunggu pulih",IF(H20=1,"MAIN SEKARANG",IF(ISNUMBER(H20),"Main urutan "&H20,"-")))&IF(M20=1," | PRIORITAS NAIK GS","")) -> Main urutan 5
A21: Averroes | B21: 1595 | C21: 1575 | D21: =IF(OR(A21="",B21=""),"",B21-C21) -> 20 | E21: Tersedia | F21: =IF(A21="","",Hitung!Y23) -> T2 | G21: =IF(A21="","",Hitung!Z23) -> 300000 | H21: =IF(A21="","",IF(Hitung!AA23<0,"-",Hitung!AB23)) -> 6 | I21: =IF(A21="","",IF(Hitung!AL23=0,"-",Hitung!AM23&" ("&FIXED(Hitung!AN23,0)&")")) -> T3 (2,100) | J21: =IF(OR(A21="",Hitung!AL23=0),"",Hitung!AO23) -> 505 | K21: =IF(OR(A21="",Hitung!AL23=0),"",Hitung!AQ23) -> 2100000 | L21: =IF(OR(A21="",Hitung!AL23=0),"",Hitung!AK23) -> 4158.4158 | M21: =IF(A21="","",IF(Hitung!AR23<0,"-",Hitung!AS23)) -> 4 | N21: =IF(A21="","",IF(Gear!W12=0,"Lengkap",Gear!W12&" item kurang (Acc "&Gear!U12&" / Gear "&Gear!V12&")")) -> 14 item kurang (Acc 6 / Gear 8) | O21: =IF(A21="","",IF(E21="Habis","Odyle habis: tunggu pulih",IF(H21=1,"MAIN SEKARANG",IF(ISNUMBER(H21),"Main urutan "&H21,"-")))&IF(M21=1," | PRIORITAS NAIK GS","")) -> Main urutan 6
A22: Claudius | B22: 1558 | C22: 1529 | D22: =IF(OR(A22="",B22=""),"",B22-C22) -> 29 | E22: Tersedia | F22: =IF(A22="","",Hitung!Y24) -> T2 | G22: =IF(A22="","",Hitung!Z24) -> 300000 | H22: =IF(A22="","",IF(Hitung!AA24<0,"-",Hitung!AB24)) -> 7 | I22: =IF(A22="","",IF(Hitung!AL24=0,"-",Hitung!AM24&" ("&FIXED(Hitung!AN24,0)&")")) -> T3 (2,100) | J22: =IF(OR(A22="",Hitung!AL24=0),"",Hitung!AO24) -> 542 | K22: =IF(OR(A22="",Hitung!AL24=0),"",Hitung!AQ24) -> 2100000 | L22: =IF(OR(A22="",Hitung!AL24=0),"",Hitung!AK24) -> 3874.5387 | M22: =IF(A22="","",IF(Hitung!AR24<0,"-",Hitung!AS24)) -> 6 | N22: =IF(A22="","",IF(Gear!W13=0,"Lengkap",Gear!W13&" item kurang (Acc "&Gear!U13&" / Gear "&Gear!V13&")")) -> 14 item kurang (Acc 6 / Gear 8) | O22: =IF(A22="","",IF(E22="Habis","Odyle habis: tunggu pulih",IF(H22=1,"MAIN SEKARANG",IF(ISNUMBER(H22),"Main urutan "&H22,"-")))&IF(M22=1," | PRIORITAS NAIK GS","")) -> Main urutan 7
A24: PREDIKSI KINA MINGGU INI
F25: Kapasitas cube minggu ini (semua karakter) | M25: =Setting!E52 -> 208
F26: Cube terpakai (perkiraan = play count Conquest + Transcend) | M26: =B5+B6 -> 55
F27: Sisa cube (perkiraan) | M27: =MAX(0,M25-M26) -> 153
F28: Kina yang sudah didapat (perkiraan) | M28: =Hitung!AP13 -> 17400000
F29: PREDIKSI kina dari sisa cube (kotor) | M29: =Hitung!AO13-Hitung!AP13 -> 48300000
F30: PREDIKSI total kina minggu ini (kotor, maksimal) | M30: =Hitung!AO13 -> 65700000
F31: Biaya craft + shop (rencana, dari sheet Setting) | M31: =Setting!H52 -> 3000000
F32: PREDIKSI total kina BERSIH (maksimal) | M32: =M30-M31 -> 62700000
A34: RENCANA PER MODE
F35: Mode | G35: Kategori | H35: Cube direncanakan | I35: Kina prediksi | L35: Rata-rata / cube
F36: =IF(Hitung!B5="","",Hitung!B5) -> T2 | G36: =IF(F36="","",Hitung!C5) -> Conquest | H36: =IF(F36="","",Hitung!M5) -> 105 | I36: =IF(F36="","",Hitung!AO5) -> 30240000 | L36: =IF(OR(F36="",N(H36)=0),"",I36/H36) -> 288000
F37: =IF(Hitung!B6="","",Hitung!B6) -> T3 | G37: =IF(F37="","",Hitung!C6) -> Conquest | H37: =IF(F37="","",Hitung!M6) -> 0 | I37: =IF(F37="","",Hitung!AO6) -> 0 | L37: =IF(OR(F37="",N(H37)=0),"",I37/H37)
F38: =IF(Hitung!B7="","",Hitung!B7) -> S1 | G38: =IF(F38="","",Hitung!C7) -> Transcend | H38: =IF(F38="","",Hitung!M7) -> 42 | I38: =IF(F38="","",Hitung!AO7) -> 6660000 | L38: =IF(OR(F38="",N(H38)=0),"",I38/H38) -> 158571.43
F39: =IF(Hitung!B8="","",Hitung!B8) -> S2 | G39: =IF(F39="","",Hitung!C8) -> Transcend | H39: =IF(F39="","",Hitung!M8) -> 0 | I39: =IF(F39="","",Hitung!AO8) -> 0 | L39: =IF(OR(F39="",N(H39)=0),"",I39/H39)
F40: =IF(Hitung!B9="","",Hitung!B9) -> S3 | G40: =IF(F40="","",Hitung!C9) -> Transcend | H40: =IF(F40="","",Hitung!M9) -> 0 | I40: =IF(F40="","",Hitung!AO9) -> 0 | L40: =IF(OR(F40="",N(H40)=0),"",I40/H40)
F41: =IF(Hitung!B10="","",Hitung!B10) -> S4 | G41: =IF(F41="","",Hitung!C10) -> Transcend | H41: =IF(F41="","",Hitung!M10) -> 61 | I41: =IF(F41="","",Hitung!AO10) -> 28800000 | L41: =IF(OR(F41="",N(H41)=0),"",I41/H41) -> 472131.15
F42: =IF(Hitung!B11="","",Hitung!B11) | G42: =IF(F42="","",Hitung!C11) | H42: =IF(F42="","",Hitung!M11) | I42: =IF(F42="","",Hitung!AO11) | L42: =IF(OR(F42="",N(H42)=0),"",I42/H42)
F43: =IF(Hitung!B12="","",Hitung!B12) | G43: =IF(F43="","",Hitung!C12) | H43: =IF(F43="","",Hitung!M12) | I43: =IF(F43="","",Hitung!AO12) | L43: =IF(OR(F43="",N(H43)=0),"",I43/H43)
A46: CATATAN & ASUMSI
A47: - Prediksi: semua cube kapasitas dimainkan; tiap karakter memakai mode berkina terbaik yang sesuai GS-nya (dihitung pada tier perkiraan akhir minggu); dalam tiap kategori, reward tertinggi dimainkan lebih dulu.
A48: - Cube terpakai dianggap = play count (1 play = 1 cube, semua karakter 1 cube/main). 'Kina sudah didapat' mengasumsikan play yang lalu sudah berurutan dari reward tertinggi.
...

Sheet Gear
A1: Gear Checklist
A2: Pilih ✔ di sel yang gear-nya SUDAH didapat (kosong = belum). Data awal diambil dari Item_Tracker. Jumlah yang kurang dihitung otomatis.
C3: ACCESSORIES | J3: GEAR
A5: Karakter | B5: Tipe | C5: Set Accessories | D5: Wpn | E5: Ear L | F5: Ear R | G5: Neck | H5: Ring L | I5: Ring R | J5: Set Gear | K5: Guards | L5: Breastplate | M5: Greaves | N5: Helm | O5: Pauldrons | P5: Gloves | Q5: Boots | R5: Cloak | S5: Arkanis | T5: Deus | U5: Kurang Acc | V5: Kurang Gear | W5: Total kurang
A6: =IF(Dashboard!A15="","",Dashboard!A15) -> ChromeT | B6: 🛡️ | C6: Kromede | D6: TRUE | E6: TRUE | F6: TRUE | G6: FALSE | H6: TRUE | I6: TRUE | J6: Horn Den | K6: FALSE | L6: TRUE | M6: FALSE | N6: TRUE | O6: FALSE | P6: TRUE | Q6: TRUE | R6: TRUE | S6: 4 | T6: 4 | U6: =6-COUNTIF(D6:I6,"TRUE") -> 1 | V6: =8-COUNTIF(K6:R6,"TRUE") -> 3 | W6: =U6+V6 -> 4
A7: =IF(Dashboard!A16="","",Dashboard!A16) -> Roxarika | B7: 🛡️ | C7: Urugugu | D7: FALSE | E7: FALSE | F7: FALSE | G7: FALSE | H7: FALSE | I7: FALSE | J7: Vakron | K7: FALSE | L7: FALSE | M7: FALSE | N7: FALSE | O7: FALSE | P7: FALSE | Q7: FALSE | R7: FALSE | S7: 4 | T7: 4 | U7: =6-COUNTIF(D7:I7,"TRUE") -> 6 | V7: =8-COUNTIF(K7:R7,"TRUE") -> 8 | W7: =U7+V7 -> 14
A8: =IF(Dashboard!A17="","",Dashboard!A17) -> Crosley | B8: 🛡️ | C8: Urugugu | D8: FALSE | E8: FALSE | F8: FALSE | G8: FALSE | H8: FALSE | I8: FALSE | J8: Vakron | K8: FALSE | L8: FALSE | M8: FALSE | N8: FALSE | O8: FALSE | P8: FALSE | Q8: FALSE | R8: FALSE | S8: 4 | T8: 4 | U8: =6-COUNTIF(D8:I8,"TRUE") -> 6 | V8: =8-COUNTIF(K8:R8,"TRUE") -> 8 | W8: =U8+V8 -> 14
A9: =IF(Dashboard!A18="","",Dashboard!A18) -> Nathanael | B9: 🛡️ | C9: Urugugu | D9: FALSE | E9: FALSE | F9: FALSE | G9: FALSE | H9: FALSE | I9: FALSE | J9: Vakron | K9: FALSE | L9: FALSE | M9: FALSE | N9: FALSE | O9: FALSE | P9: FALSE | Q9: FALSE | R9: FALSE | S9: 4 | T9: 4 | U9: =6-COUNTIF(D9:I9,"TRUE") -> 6 | V9: =8-COUNTIF(K9:R9,"TRUE") -> 8 | W9: =U9+V9 -> 14
A10: =IF(Dashboard!A19="","",Dashboard!A19) -> Cicero | B10: 🛡️ | C10: Urugugu | D10: FALSE | E10: FALSE | F10: FALSE | G10: FALSE | H10: FALSE | I10: FALSE | J10: Vakron | K10: FALSE | L10: FALSE | M10: FALSE | N10: FALSE | O10: FALSE | P10: FALSE | Q10: FALSE | R10: FALSE | S10: 4 | T10: 4 | U10: =6-COUNTIF(D10:I10,"TRUE") -> 6 | V10: =8-COUNTIF(K10:R10,"TRUE") -> 8 | W10: =U10+V10 -> 14
A11: =IF(Dashboard!A20="","",Dashboard!A20) -> Seneca | B11: 🛡️ | C11: Urugugu | D11: FALSE | E11: FALSE | F11: FALSE | G11: FALSE | H11: FALSE | I11: FALSE | J11: Vakron | K11: FALSE | L11: FALSE | M11: FALSE | N11: FALSE | O11: FALSE | P11: FALSE | Q11: FALSE | R11: FALSE | S11: 4 | T11: 4 | U11: =6-COUNTIF(D11:I11,"TRUE") -> 6 | V11: =8-COUNTIF(K11:R11,"TRUE") -> 8 | W11: =U11+V11 -> 14
A12: =IF(Dashboard!A21="","",Dashboard!A21) -> Averroes | B12: 🛡️ | C12: Urugugu | D12: FALSE | E12: FALSE | F12: FALSE | G12: FALSE | H12: FALSE | I12: FALSE | J12: Vakron | K12: FALSE | L12: FALSE | M12: FALSE | N12: FALSE | O12: FALSE | P12: FALSE | Q12: FALSE | R12: FALSE | S12: 4 | T12: 4 | U12: =6-COUNTIF(D12:I12,"TRUE") -> 6 | V12: =8-COUNTIF(K12:R12,"TRUE") -> 8 | W12: =U12+V12 -> 14
A13: =IF(Dashboard!A22="","",Dashboard!A22) -> Claudius | B13: 🛡️ | C13: Urugugu | D13: FALSE | E13: FALSE | F13: FALSE | G13: FALSE | H13: FALSE | I13: FALSE | J13: Vakron | K13: FALSE | L13: FALSE | M13: FALSE | N13: FALSE | O13: FALSE | P13: FALSE | Q13: FALSE | R13: FALSE | S13: 4 | T13: 4 | U13: =6-COUNTIF(D13:I13,"TRUE") -> 6 | V13: =8-COUNTIF(K13:R13,"TRUE") -> 8 | W13: =U13+V13 -> 14

Sheet Setting
A1: Setting
A2: Biru = angka yang boleh diubah. Hitam = rumus. Biasanya tidak perlu dibuka kecuali reward / bracket / harga berubah.
A4: Parameter | B4: Nilai | C4: Keterangan
A5: Energi per cube (1 run) | B5: 40 | C5: Dari screenshot: Cube Reward = 40 energi.
A6: Regen energi per interval | B6: 15 | C6: Dari kamu: 15 per 3 jam.
A7: Interval regen (jam) | B7: 3 | C7: Dari kamu.
A8: Energi gratis per karakter / minggu | B8: =B6*(24/B7)*7 -> 840 | C8: Rumus: 15 x 8 x 7 = 840.
A9: Energi per 1 craft / 1 stone shop | B9: 40 | C9: Dari kamu: 1 craft / 1 pembelian = 40 energi.
A10: Biaya kina per craft | B10: 50000 | C10: Dari template Kalkulator (sumber guide web, verifikasi di game).
A11: Biaya material tambahan per craft (kina) | B11: 0 | C11: Opsional: isi nilai pasar material craft jika mau dihitung.
A12: Harga shop per 1 stone (kina) | B12: 100000 | C12: Dari template Kalkulator (sumber guide web, verifikasi di game).
A13: Batas craft per karakter / minggu | B13: 4 | C13: Dari kamu: 4 x 40 energi.
A14: Batas craft per server / minggu | B14: 16 | C14: Dari kamu: 16 x 40 energi (dibagi ke karakter mana saja).
A15: Batas beli shop per karakter / minggu | B15: 20 | C15: Dari kamu: 20 x 40 energi.
A17: DAFTAR MODE / DUNGEON
A18: No | B18: Mode | C18: Kategori | D18: Kina reward (100%) | E18: Min GS | F18: Keterangan
A19: 1 | B19: T2 | C19: Conquest | D19: 300000 | E19: 1400 | F19: Vakron (angka dari kamu)
A20: 2 | B20: T3 | C20: Conquest | D20: 400000 | E20: 2100 | F20: Fire Temple (angka dari kamu)
A21: 3 | B21: S1 | C21: Transcend | D21: 300000 | E21: 1600 | F21: Transcend Stage 1 (angka dari kamu)
A22: 4 | B22: S2 | C22: Transcend | D22: 360000 | E22: 1900 | F22: Transcend Stage 2 (angka dari kamu)
A23: 5 | B23: S3 | C23: Transcend | D23: 420000 | E23: 2200 | F23: PERKIRAAN reward 420.000 (dari template). Ganti dengan angka asli.
A24: 6 | B24: S4 | C24: Transcend | D24: 480000 | E24: 2500 | F24: Angka dari template Kalkulator.
A25: 7
A26: 8
A27: Mode baru: isi di baris kosong (kategori Conquest / Transcend). Baris kosong diabaikan.
A28: BRACKET PLAY COUNT (pengurangan kina)
A29: Kategori | B29: Level | C29: Mulai (play count) | D29: Sampai | E29: Multiplier kina
A30: Conquest | B30: 1 | C30: 0 | D30: =C31-1 -> 83 | E30: 1
A31: Conquest | B31: 2 | C31: 84 | D31: =C32-1 -> 104 | E31: 0.8
A32: Conquest | B32: 3 | C32: 105 | D32: =C33-1 -> 125 | E32: 0.6
A33: Conquest | B33: 4 | C33: 126 | D33: =C34-1 -> 146 | E33: 0.4
A34: Conquest | B34: 5 | C34: 147 | D34: 999999 | E34: 0.2
A35: Transcend | B35: 1 | C35: 0 | D35: =C36-1 -> 55 | E35: 1
A36: Transcend | B36: 2 | C36: 56 | D36: =C37-1 -> 69 | E36: 0.8
A37: Transcend | B37: 3 | C37: 70 | D37: =C38-1 -> 83 | E37: 0.6
A38: Transcend | B38: 4 | C38: 84 | D38: =C39-1 -> 97 | E38: 0.4
A39: Transcend | B39: 5 | C39: 98 | D39: 999999 | E39: 0.2
A40: Sumber: screenshot 'Cumulative Play Reward Adjustment' dari kamu. 999.999 = tak terbatas. 'Mulai' = play count saat run dimulai (84 -> tier 80%).
A42: RENCANA ENERGI TAMBAHAN PER KARAKTER (craft & shop)
A43: Karakter | B43: Craft karakter (jml) | C43: Craft server dialokasikan | D43: Beli shop (jml) | E43: Cube / minggu (maks) | F43: Biaya craft (kina) | G43: Biaya shop (kina) | H43: Total biaya (kina)
...

Sheet Hitung
A1: Hitung (mesin perhitungan)
A2: Tidak perlu dibuka atau diedit.
A4: No | B4: Mode | C4: Kategori | D4: Kina full | E4: Min GS | F4: Play count skrg | G4: Mult skrg | H4: Kina/cube skrg | I4: Cube pass1 | J4: Total cat pass1 | K4: Mult acuan | L4: Kina/cube acuan | M4: Cube rencana | N4: Mulai (posisi) | O4: Akhir (posisi) | P4: Ov L1 | Q4: Ov L2 | R4: Ov L3 | S4: Ov L4 | T4: Ov L5 | U4: OvDone L1 | V4: OvDone L2 | W4: OvDone L3 | X4: OvDone L4 | Y4: OvDone L5 | Z4: Mult L1 | AA4: Mult L2 | AB4: Mult L3 | AC4: Mult L4 | AD4: Mult L5 | AE4: Lo L1 | AF4: Lo L2 | AG4: Lo L3 | AH4: Lo L4 | AI4: Lo L5 | AJ4: Hi L1 | AK4: Hi L2 | AL4: Hi L3 | AM4: Hi L4 | AN4: Hi L5 | AO4: Kina rencana | AP4: Kina sudah
A5: 1 | B5: =IF(Setting!B19="","",Setting!B19) -> T2 | C5: =IF(B5="","",Setting!C19) -> Conquest | D5: =IF(B5="",0,N(Setting!D19)) -> 300000 | E5: =IF(B5="",0,N(Setting!E19)) -> 1400 | F5: =IF(C5="Conquest",Dashboard!$B$5,IF(C5="Transcend",Dashboard!$B$6,0)) -> 50 | G5: =IF(B5="",0,SUMIFS(Setting!$E$30:$E$39,Setting!$A$30:$A$39,C5,Setting!$C$30:$C$39,"<="&F5,Setting!$D$30:$D$39,">="&F5)) -> 1 | H5: =D5*G5 -> 300000 | I5: =SUMIF($N$17:$N$24,A5,$D$17:$D$24) -> 147 | J5: =IF(B5="",0,SUMIF($C$5:$C$12,C5,$I$5:$I$12)) -> 147 | K5: =IF(B5="",0,SUMIFS(Setting!$E$30:$E$39,Setting!$A$30:$A$39,C5,Setting!$C$30:$C$39,"<="&J5,Setting!$D$30:$D$39,">="&J5)) -> 0.2 | L5: =D5*K5 -> 60000 | M5: =SUMIF($X$17:$X$24,A5,$D$17:$D$24) -> 105 | N5: =IF(B5="",0,SUMPRODUCT(($C$5:$C$12=C5)*(($D$5:$D$12>D5)+($D$5:$D$12=D5)*($A$5:$A$12<A5))*$M$5:$M$12)) -> 0 | O5: =N5+M5 -> 105 | P5: =IF($M5=0,0,MAX(0,MIN($O5-1,AJ5)-MAX($N5,AE5)+1)) -> 84 | Q5: =IF($M5=0,0,MAX(0,MIN($O5-1,AK5)-MAX($N5,AF5)+1)) -> 21 | R5: =IF($M5=0,0,MAX(0,MIN($O5-1,AL5)-MAX($N5,AG5)+1)) -> 0 | S5: =IF($M5=0,0,MAX(0,MIN($O5-1,AM5)-MAX($N5,AH5)+1)) -> 0 | T5: =IF($M5=0,0,MAX(0,MIN($O5-1,AN5)-MAX($N5,AI5)+1)) -> 0 | U5: =IF($M5=0,0,MAX(0,MIN($O5-1,AJ5,$F5-1)-MAX($N5,AE5)+1)) -> 50 | V5: =IF($M5=0,0,MAX(0,MIN($O5-1,AK5,$F5-1)-MAX($N5,AF5)+1)) -> 0 | W5: =IF($M5=0,0,MAX(0,MIN($O5-1,AL5,$F5-1)-MAX($N5,AG5)+1)) -> 0 | X5: =IF($M5=0,0,MAX(0,MIN($O5-1,AM5,$F5-1)-MAX($N5,AH5)+1)) -> 0 | Y5: =IF($M5=0,0,MAX(0,MIN($O5-1,AN5,$F5-1)-MAX($N5,AI5)+1)) -> 0 | Z5: =IF($B5="",0,SUMIFS(Setting!$E$30:$E$39,Setting!$A$30:$A$39,$C5,Setting!$B$30:$B$39,1)) -> 1 | AA5: =IF($B5="",0,SUMIFS(Setting!$E$30:$E$39,Setting!$A$30:$A$39,$C5,Setting!$B$30:$B$39,2)) -> 0.8 | AB5: =IF($B5="",0,SUMIFS(Setting!$E$30:$E$39,Setting!$A$30:$A$39,$C5,Setting!$B$30:$B$39,3)) -> 0.6 | AC5: =IF($B5="",0,SUMIFS(Setting!$E$30:$E$39,Setting!$A$30:$A$39,$C5,Setting!$B$30:$B$39,4)) -> 0.4 | AD5: =IF($B5="",0,SUMIFS(Setting!$E$30:$E$39,Setting!$A$30:$A$39,$C5,Setting!$B$30:$B$39,5)) -> 0.2 | AE5: =IF($B5="",0,SUMIFS(Setting!$C$30:$C$39,Setting!$A$30:$A$39,$C5,Setting!$B$30:$B$39,1)) -> 0 | AF5: =IF($B5="",0,SUMIFS(Setting!$C$30:$C$39,Setting!$A$30:$A$39,$C5,Setting!$B$30:$B$39,2)) -> 84 | AG5: =IF($B5="",0,SUMIFS(Setting!$C$30:$C$39,Setting!$A$30:$A$39,$C5,Setting!$B$30:$B$39,3)) -> 105 | AH5: =IF($B5="",0,SUMIFS(Setting!$C$30:$C$39,Setting!$A$30:$A$39,$C5,Setting!$B$30:$B$39,4)) -> 126 | AI5: =IF($B5="",0,SUMIFS(Setting!$C$30:$C$39,Setting!$A$30:$A$39,$C5,Setting!$B$30:$B$39,5)) -> 147 | AJ5: =IF($B5="",0,SUMIFS(Setting!$D$30:$D$39,Setting!$A$30:$A$39,$C5,Setting!$B$30:$B$39,1)) -> 83 | AK5: =IF($B5="",0,SUMIFS(Setting!$D$30:$D$39,Setting!$A$30:$A$39,$C5,Setting!$B$30:$B$39,2)) -> 104 | AL5: =IF($B5="",0,SUMIFS(Setting!$D$30:$D$39,Setting!$A$30:$A$39,$C5,Setting!$B$30:$B$39,3)) -> 125 | AM5: =IF($B5="",0,SUMIFS(Setting!$D$30:$D$39,Setting!$A$30:$A$39,$C5,Setting!$B$30:$B$39,4)) -> 146 | AN5: =IF($B5="",0,SUMIFS(Setting!$D$30:$D$39,Setting!$A$30:$A$39,$C5,Setting!$B$30:$B$39,5)) -> 999999 | AO5: =$D5*SUMPRODUCT(P5:T5,Z5:AD5) -> 30240000 | AP5: =$D5*SUMPRODUCT(U5:Y5,Z5:AD5) -> 15000000
A6: 2 | B6: =IF(Setting!B20="","",Setting!B20) -> T3 | C6: =IF(B6="","",Setting!C20) -> Conquest | D6: =IF(B6="",0,N(Setting!D20)) -> 400000 | E6: =IF(B6="",0,N(Setting!E20)) -> 2100 | F6: =IF(C6="Conquest",Dashboard!$B$5,IF(C6="Transcend",Dashboard!$B$6,0)) -> 50 | G6: =IF(B6="",0,SUMIFS(Setting!$E$30:$E$39,Setting!$A$30:$A$39,C6,Setting!$C$30:$C$39,"<="&F6,Setting!$D$30:$D$39,">="&F6)) -> 1 | H6: =D6*G6 -> 400000 | I6: =SUMIF($N$17:$N$24,A6,$D$17:$D$24) -> 0 | J6: =IF(B6="",0,SUMIF($C$5:$C$12,C6,$I$5:$I$12)) -> 147 | K6: =IF(B6="",0,SUMIFS(Setting!$E$30:$E$39,Setting!$A$30:$A$39,C6,Setting!$C$30:$C$39,"<="&J6,Setting!$D$30:$D$39,">="&J6)) -> 0.2 | L6: =D6*K6 -> 80000 | M6: =SUMIF($X$17:$X$24,A6,$D$17:$D$24) -> 0 | N6: =IF(B6="",0,SUMPRODUCT(($C$5:$C$12=C6)*(($D$5:$D$12>D6)+($D$5:$D$12=D6)*($A$5:$A$12<A6))*$M$5:$M$12)) -> 0 | O6: =N6+M6 -> 0 | P6: =IF($M6=0,0,MAX(0,MIN($O6-1,AJ6)-MAX($N6,AE6)+1)) -> 0 | Q6: =IF($M6=0,0,MAX(0,MIN($O6-1,AK6)-MAX($N6,AF6)+1)) -> 0 | R6: =IF($M6=0,0,MAX(0,MIN($O6-1,AL6)-MAX($N6,AG6)+1)) -> 0 | S6: =IF($M6=0,0,MAX(0,MIN($O6-1,AM6)-MAX($N6,AH6)+1)) -> 0 | T6: =IF($M6=0,0,MAX(0,MIN($O6-1,AN6)-MAX($N6,AI6)+1)) -> 0 | U6: =IF($M6=0,0,MAX(0,MIN($O6-1,AJ6,$F6-1)-MAX($N6,AE6)+1)) -> 0 | V6: =IF($M6=0,0,MAX(0,MIN($O6-1,AK6,$F6-1)-MAX($N6,AF6)+1)) -> 0 | W6: =IF($M6=0,0,MAX(0,MIN($O6-1,AL6,$F6-1)-MAX($N6,AG6)+1)) -> 0 | X6: =IF($M6=0,0,MAX(0,MIN($O6-1,AM6,$F6-1)-MAX($N6,AH6)+1)) -> 0 | Y6: =IF($M6=0,0,MAX(0,MIN($O6-1,AN6,$F6-1)-MAX($N6,AI6)+1)) -> 0 | Z6: =IF($B6="",0,SUMIFS(Setting!$E$30:$E$39,Setting!$A$30:$A$39,$C6,Setting!$B$30:$B$39,1)) -> 1 | AA6: =IF($B6="",0,SUMIFS(Setting!$E$30:$E$39,Setting!$A$30:$A$39,$C6,Setting!$B$30:$B$39,2)) -> 0.8 | AB6: =IF($B6="",0,SUMIFS(Setting!$E$30:$E$39,Setting!$A$30:$A$39,$C6,Setting!$B$30:$B$39,3)) -> 0.6 | AC6: =IF($B6="",0,SUMIFS(Setting!$E$30:$E$39,Setting!$A$30:$A$39,$C6,Setting!$B$30:$B$39,4)) -> 0.4 | AD6: =IF($B6="",0,SUMIFS(Setting!$E$30:$E$39,Setting!$A$30:$A$39,$C6,Setting!$B$30:$B$39,5)) -> 0.2 | AE6: =IF($B6="",0,SUMIFS(Setting!$C$30:$C$39,Setting!$A$30:$A$39,$C6,Setting!$B$30:$B$39,1)) -> 0 | AF6: =IF($B6="",0,SUMIFS(Setting!$C$30:$C$39,Setting!$A$30:$A$39,$C6,Setting!$B$30:$B$39,2)) -> 84 | AG6: =IF($B6="",0,SUMIFS(Setting!$C$30:$C$39,Setting!$A$30:$A$39,$C6,Setting!$B$30:$B$39,3)) -> 105 | AH6: =IF($B6="",0,SUMIFS(Setting!$C$30:$C$39,Setting!$A$30:$A$39,$C6,Setting!$B$30:$B$39,4)) -> 126 | AI6: =IF($B6="",0,SUMIFS(Setting!$C$30:$C$39,Setting!$A$30:$A$39,$C6,Setting!$B$30:$B$39,5)) -> 147 | AJ6: =IF($B6="",0,SUMIFS(Setting!$D$30:$D$39,Setting!$A$30:$A$39,$C6,Setting!$B$30:$B$39,1)) -> 83 | AK6: =IF($B6="",0,SUMIFS(Setting!$D$30:$D$39,Setting!$A$30:$A$39,$C6,Setting!$B$30:$B$39,2)) -> 104 | AL6: =IF($B6="",0,SUMIFS(Setting!$D$30:$D$39,Setting!$A$30:$A$39,$C6,Setting!$B$30:$B$39,3)) -> 125 | AM6: =IF($B6="",0,SUMIFS(Setting!$D$30:$D$39,Setting!$A$30:$A$39,$C6,Setting!$B$30:$B$39,4)) -> 146 | AN6: =IF($B6="",0,SUMIFS(Setting!$D$30:$D$39,Setting!$A$30:$A$39,$C6,Setting!$B$30:$B$39,5)) -> 999999 | AO6: =$D6*SUMPRODUCT(P6:T6,Z6:AD6) -> 0 | AP6: =$D6*SUMPRODUCT(U6:Y6,Z6:AD6) -> 0
A7: 3 | B7: =IF(Setting!B21="","",Setting!B21) -> S1 | C7: =IF(B7="","",Setting!C21) -> Transcend | D7: =IF(B7="",0,N(Setting!D21)) -> 300000 | E7: =IF(B7="",0,N(Setting!E21)) -> 1600 | F7: =IF(C7="Conquest",Dashboard!$B$5,IF(C7="Transcend",Dashboard!$B$6,0)) -> 5 | G7: =IF(B7="",0,SUMIFS(Setting!$E$30:$E$39,Setting!$A$30:$A$39,C7,Setting!$C$30:$C$39,"<="&F7,Setting!$D$30:$D$39,">="&F7)) -> 1 | H7: =D7*G7 -> 300000 | I7: =SUMIF($N$17:$N$24,A7,$D$17:$D$24) -> 0 | J7: =IF(B7="",0,SUMIF($C$5:$C$12,C7,$I$5:$I$12)) -> 61 | K7: =IF(B7="",0,SUMIFS(Setting!$E$30:$E$39,Setting!$A$30:$A$39,C7,Setting!$C$30:$C$39,"<="&J7,Setting!$D$30:$D$39,">="&J7)) -> 0.8 | L7: =D7*K7 -> 240000 | M7: =SUMIF($X$17:$X$24,A7,$D$17:$D$24) -> 42 | N7: =IF(B7="",0,SUMPRODUCT(($C$5:$C$12=C7)*(($D$5:$D$12>D7)+($D$5:$D$12=D7)*($A$5:$A$12<A7))*$M$5:$M$12)) -> 61 | O7: =N7+M7 -> 103 | P7: =IF($M7=0,0,MAX(0,MIN($O7-1,AJ7)-MAX($N7,AE7)+1)) -> 0 | Q7: =IF($M7=0,0,MAX(0,MIN($O7-1,AK7)-MAX($N7,AF7)+1)) -> 9 | R7: =IF($M7=0,0,MAX(0,MIN($O7-1,AL7)-MAX($N7,AG7)+1)) -> 14 | S7: =IF($M7=0,0,MAX(0,MIN($O7-1,AM7)-MAX($N7,AH7)+1)) -> 14 | T7: =IF($M7=0,0,MAX(0,MIN($O7-1,AN7)-MAX($N7,AI7)+1)) -> 5 | U7: =IF($M7=0,0,MAX(0,MIN($O7-1,AJ7,$F7-1)-MAX($N7,AE7)+1)) -> 0 | V7: =IF($M7=0,0,MAX(0,MIN($O7-1,AK7,$F7-1)-MAX($N7,AF7)+1)) -> 0 | W7: =IF($M7=0,0,MAX(0,MIN($O7-1,AL7,$F7-1)-MAX($N7,AG7)+1)) -> 0 | X7: =IF($M7=0,0,MAX(0,MIN($O7-1,AM7,$F7-1)-MAX($N7,AH7)+1)) -> 0 | Y7: =IF($M7=0,0,MAX(0,MIN($O7-1,AN7,$F7-1)-MAX($N7,AI7)+1)) -> 0 | Z7: =IF($B7="",0,SUMIFS(Setting!$E$30:$E$39,Setting!$A$30:$A$39,$C7,Setting!$B$30:$B$39,1)) -> 1 | AA7: =IF($B7="",0,SUMIFS(Setting!$E$30:$E$39,Setting!$A$30:$A$39,$C7,Setting!$B$30:$B$39,2)) -> 0.8 | AB7: =IF($B7="",0,SUMIFS(Setting!$E$30:$E$39,Setting!$A$30:$A$39,$C7,Setting!$B$30:$B$39,3)) -> 0.6 | AC7: =IF($B7="",0,SUMIFS(Setting!$E$30:$E$39,Setting!$A$30:$A$39,$C7,Setting!$B$30:$B$39,4)) -> 0.4 | AD7: =IF($B7="",0,SUMIFS(Setting!$E$30:$E$39,Setting!$A$30:$A$39,$C7,Setting!$B$30:$B$39,5)) -> 0.2 | AE7: =IF($B7="",0,SUMIFS(Setting!$C$30:$C$39,Setting!$A$30:$A$39,$C7,Setting!$B$30:$B$39,1)) -> 0 | AF7: =IF($B7="",0,SUMIFS(Setting!$C$30:$C$39,Setting!$A$30:$A$39,$C7,Setting!$B$30:$B$39,2)) -> 56 | AG7: =IF($B7="",0,SUMIFS(Setting!$C$30:$C$39,Setting!$A$30:$A$39,$C7,Setting!$B$30:$B$39,3)) -> 70 | AH7: =IF($B7="",0,SUMIFS(Setting!$C$30:$C$39,Setting!$A$30:$A$39,$C7,Setting!$B$30:$B$39,4)) -> 84 | AI7: =IF($B7="",0,SUMIFS(Setting!$C$30:$C$39,Setting!$A$30:$A$39,$C7,Setting!$B$30:$B$39,5)) -> 98 | AJ7: =IF($B7="",0,SUMIFS(Setting!$D$30:$D$39,Setting!$A$30:$A$39,$C7,Setting!$B$30:$B$39,1)) -> 55 | AK7: =IF($B7="",0,SUMIFS(Setting!$D$30:$D$39,Setting!$A$30:$A$39,$C7,Setting!$B$30:$B$39,2)) -> 69 | AL7: =IF($B7="",0,SUMIFS(Setting!$D$30:$D$39,Setting!$A$30:$A$39,$C7,Setting!$B$30:$B$39,3)) -> 83 | AM7: =IF($B7="",0,SUMIFS(Setting!$D$30:$D$39,Setting!$A$30:$A$39,$C7,Setting!$B$30:$B$39,4)) -> 97 | AN7: =IF($B7="",0,SUMIFS(Setting!$D$30:$D$39,Setting!$A$30:$A$39,$C7,Setting!$B$30:$B$39,5)) -> 999999 | AO7: =$D7*SUMPRODUCT(P7:T7,Z7:AD7) -> 6660000 | AP7: =$D7*SUMPRODUCT(U7:Y7,Z7:AD7) -> 0
A8: 4 | B8: =IF(Setting!B22="","",Setting!B22) -> S2 | C8: =IF(B8="","",Setting!C22) -> Transcend | D8: =IF(B8="",0,N(Setting!D22)) -> 360000 | E8: =IF(B8="",0,N(Setting!E22)) -> 1900 | F8: =IF(C8="Conquest",Dashboard!$B$5,IF(C8="Transcend",Dashboard!$B$6,0)) -> 5 | G8: =IF(B8="",0,SUMIFS(Setting!$E$30:$E$39,Setting!$A$30:$A$39,C8,Setting!$C$30:$C$39,"<="&F8,Setting!$D$30:$D$39,">="&F8)) -> 1 | H8: =D8*G8 -> 360000 | I8: =SUMIF($N$17:$N$24,A8,$D$17:$D$24) -> 0 | J8: =IF(B8="",0,SUMIF($C$5:$C$12,C8,$I$5:$I$12)) -> 61 | K8: =IF(B8="",0,SUMIFS(Setting!$E$30:$E$39,Setting!$A$30:$A$39,C8,Setting!$C$30:$C$39,"<="&J8,Setting!$D$30:$D$39,">="&J8)) -> 0.8 | L8: =D8*K8 -> 288000 | M8: =SUMIF($X$17:$X$24,A8,$D$17:$D$24) -> 0 | N8: =IF(B8="",0,SUMPRODUCT(($C$5:$C$12=C8)*(($D$5:$D$12>D8)+($D$5:$D$12=D8)*($A$5:$A$12<A8))*$M$5:$M$12)) -> 61 | O8: =N8+M8 -> 61 | P8: =IF($M8=0,0,MAX(0,MIN($O8-1,AJ8)-MAX($N8,AE8)+1)) -> 0 | Q8: =IF($M8=0,0,MAX(0,MIN($O8-1,AK8)-MAX($N8,AF8)+1)) -> 0 | R8: =IF($M8=0,0,MAX(0,MIN($O8-1,AL8)-MAX($N8,AG8)+1)) -> 0 | S8: =IF($M8=0,0,MAX(0,MIN($O8-1,AM8)-MAX($N8,AH8)+1)) -> 0 | T8: =IF($M8=0,0,MAX(0,MIN($O8-1,AN8)-MAX($N8,AI8)+1)) -> 0 | U8: =IF($M8=0,0,MAX(0,MIN($O8-1,AJ8,$F8-1)-MAX($N8,AE8)+1)) -> 0 | V8: =IF($M8=0,0,MAX(0,MIN($O8-1,AK8,$F8-1)-MAX($N8,AF8)+1)) -> 0 | W8: =IF($M8=0,0,MAX(0,MIN($O8-1,AL8,$F8-1)-MAX($N8,AG8)+1)) -> 0 | X8: =IF($M8=0,0,MAX(0,MIN($O8-1,AM8,$F8-1)-MAX($N8,AH8)+1)) -> 0 | Y8: =IF($M8=0,0,MAX(0,MIN($O8-1,AN8,$F8-1)-MAX($N8,AI8)+1)) -> 0 | Z8: =IF($B8="",0,SUMIFS(Setting!$E$30:$E$39,Setting!$A$30:$A$39,$C8,Setting!$B$30:$B$39,1)) -> 1 | AA8: =IF($B8="",0,SUMIFS(Setting!$E$30:$E$39,Setting!$A$30:$A$39,$C8,Setting!$B$30:$B$39,2)) -> 0.8 | AB8: =IF($B8="",0,SUMIFS(Setting!$E$30:$E$39,Setting!$A$30:$A$39,$C8,Setting!$B$30:$B$39,3)) -> 0.6 | AC8: =IF($B8="",0,SUMIFS(Setting!$E$30:$E$39,Setting!$A$30:$A$39,$C8,Setting!$B$30:$B$39,4)) -> 0.4 | AD8: =IF($B8="",0,SUMIFS(Setting!$E$30:$E$39,Setting!$A$30:$A$39,$C8,Setting!$B$30:$B$39,5)) -> 0.2 | AE8: =IF($B8="",0,SUMIFS(Setting!$C$30:$C$39,Setting!$A$30:$A$39,$C8,Setting!$B$30:$B$39,1)) -> 0 | AF8: =IF($B8="",0,SUMIFS(Setting!$C$30:$C$39,Setting!$A$30:$A$39,$C8,Setting!$B$30:$B$39,2)) -> 56 | AG8: =IF($B8="",0,SUMIFS(Setting!$C$30:$C$39,Setting!$A$30:$A$39,$C8,Setting!$B$30:$B$39,3)) -> 70 | AH8: =IF($B8="",0,SUMIFS(Setting!$C$30:$C$39,Setting!$A$30:$A$39,$C8,Setting!$B$30:$B$39,4)) -> 84 | AI8: =IF($B8="",0,SUMIFS(Setting!$C$30:$C$39,Setting!$A$30:$A$39,$C8,Setting!$B$30:$B$39,5)) -> 98 | AJ8: =IF($B8="",0,SUMIFS(Setting!$D$30:$D$39,Setting!$A$30:$A$39,$C8,Setting!$B$30:$B$39,1)) -> 55 | AK8: =IF($B8="",0,SUMIFS(Setting!$D$30:$D$39,Setting!$A$30:$A$39,$C8,Setting!$B$30:$B$39,2)) -> 69 | AL8: =IF($B8="",0,SUMIFS(Setting!$D$30:$D$39,Setting!$A$30:$A$39,$C8,Setting!$B$30:$B$39,3)) -> 83 | AM8: =IF($B8="",0,SUMIFS(Setting!$D$30:$D$39,Setting!$A$30:$A$39,$C8,Setting!$B$30:$B$39,4)) -> 97 | AN8: =IF($B8="",0,SUMIFS(Setting!$D$30:$D$39,Setting!$A$30:$A$39,$C8,Setting!$B$30:$B$39,5)) -> 999999 | AO8: =$D8*SUMPRODUCT(P8:T8,Z8:AD8) -> 0 | AP8: =$D8*SUMPRODUCT(U8:Y8,Z8:AD8) -> 0
A9: 5 | B9: =IF(Setting!B23="","",Setting!B23) -> S3 | C9: =IF(B9="","",Setting!C23) -> Transcend | D9: =IF(B9="",0,N(Setting!D23)) -> 420000 | E9: =IF(B9="",0,N(Setting!E23)) -> 2200 | F9: =IF(C9="Conquest",Dashboard!$B$5,IF(C9="Transcend",Dashboard!$B$6,0)) -> 5 | G9: =IF(B9="",0,SUMIFS(Setting!$E$30:$E$39,Setting!$A$30:$A$39,C9,Setting!$C$30:$C$39,"<="&F9,Setting!$D$30:$D$39,">="&F9)) -> 1 | H9: =D9*G9 -> 420000 | I9: =SUMIF($N$17:$N$24,A9,$D$17:$D$24) -> 0 | J9: =IF(B9="",0,SUMIF($C$5:$C$12,C9,$I$5:$I$12)) -> 61 | K9: =IF(B9="",0,SUMIFS(Setting!$E$30:$E$39,Setting!$A$30:$A$39,C9,Setting!$C$30:$C$39,"<="&J9,Setting!$D$30:$D$39,">="&J9)) -> 0.8 | L9: =D9*K9 -> 336000 | M9: =SUMIF($X$17:$X$24,A9,$D$17:$D$24) -> 0 | N9: =IF(B9="",0,SUMPRODUCT(($C$5:$C$12=C9)*(($D$5:$D$12>D9)+($D$5:$D$12=D9)*($A$5:$A$12<A9))*$M$5:$M$12)) -> 61 | O9: =N9+M9 -> 61 | P9: =IF($M9=0,0,MAX(0,MIN($O9-1,AJ9)-MAX($N9,AE9)+1)) -> 0 | Q9: =IF($M9=0,0,MAX(0,MIN($O9-1,AK9)-MAX($N9,AF9)+1)) -> 0 | R9: =IF($M9=0,0,MAX(0,MIN($O9-1,AL9)-MAX($N9,AG9)+1)) -> 0 | S9: =IF($M9=0,0,MAX(0,MIN($O9-1,AM9)-MAX($N9,AH9)+1)) -> 0 | T9: =IF($M9=0,0,MAX(0,MIN($O9-1,AN9)-MAX($N9,AI9)+1)) -> 0 | U9: =IF($M9=0,0,MAX(0,MIN($O9-1,AJ9,$F9-1)-MAX($N9,AE9)+1)) -> 0 | V9: =IF($M9=0,0,MAX(0,MIN($O9-1,AK9,$F9-1)-MAX($N9,AF9)+1)) -> 0 | W9: =IF($M9=0,0,MAX(0,MIN($O9-1,AL9,$F9-1)-MAX($N9,AG9)+1)) -> 0 | X9: =IF($M9=0,0,MAX(0,MIN($O9-1,AM9,$F9-1)-MAX($N9,AH9)+1)) -> 0 | Y9: =IF($M9=0,0,MAX(0,MIN($O9-1,AN9,$F9-1)-MAX($N9,AI9)+1)) -> 0 | Z9: =IF($B9="",0,SUMIFS(Setting!$E$30:$E$39,Setting!$A$30:$A$39,$C9,Setting!$B$30:$B$39,1)) -> 1 | AA9: =IF($B9="",0,SUMIFS(Setting!$E$30:$E$39,Setting!$A$30:$A$39,$C9,Setting!$B$30:$B$39,2)) -> 0.8 | AB9: =IF($B9="",0,SUMIFS(Setting!$E$30:$E$39,Setting!$A$30:$A$39,$C9,Setting!$B$30:$B$39,3)) -> 0.6 | AC9: =IF($B9="",0,SUMIFS(Setting!$E$30:$E$39,Setting!$A$30:$A$39,$C9,Setting!$B$30:$B$39,4)) -> 0.4 | AD9: =IF($B9="",0,SUMIFS(Setting!$E$30:$E$39,Setting!$A$30:$A$39,$C9,Setting!$B$30:$B$39,5)) -> 0.2 | AE9: =IF($B9="",0,SUMIFS(Setting!$C$30:$C$39,Setting!$A$30:$A$39,$C9,Setting!$B$30:$B$39,1)) -> 0 | AF9: =IF($B9="",0,SUMIFS(Setting!$C$30:$C$39,Setting!$A$30:$A$39,$C9,Setting!$B$30:$B$39,2)) -> 56 | AG9: =IF($B9="",0,SUMIFS(Setting!$C$30:$C$39,Setting!$A$30:$A$39,$C9,Setting!$B$30:$B$39,3)) -> 70 | AH9: =IF($B9="",0,SUMIFS(Setting!$C$30:$C$39,Setting!$A$30:$A$39,$C9,Setting!$B$30:$B$39,4)) -> 84 | AI9: =IF($B9="",0,SUMIFS(Setting!$C$30:$C$39,Setting!$A$30:$A$39,$C9,Setting!$B$30:$B$39,5)) -> 98 | AJ9: =IF($B9="",0,SUMIFS(Setting!$D$30:$D$39,Setting!$A$30:$A$39,$C9,Setting!$B$30:$B$39,1)) -> 55 | AK9: =IF($B9="",0,SUMIFS(Setting!$D$30:$D$39,Setting!$A$30:$A$39,$C9,Setting!$B$30:$B$39,2)) -> 69 | AL9: =IF($B9="",0,SUMIFS(Setting!$D$30:$D$39,Setting!$A$30:$A$39,$C9,Setting!$B$30:$B$39,3)) -> 83 | AM9: =IF($B9="",0,SUMIFS(Setting!$D$30:$D$39,Setting!$A$30:$A$39,$C9,Setting!$B$30:$B$39,4)) -> 97 | AN9: =IF($B9="",0,SUMIFS(Setting!$D$30:$D$39,Setting!$A$30:$A$39,$C9,Setting!$B$30:$B$39,5)) -> 999999 | AO9: =$D9*SUMPRODUCT(P9:T9,Z9:AD9) -> 0 | AP9: =$D9*SUMPRODUCT(U9:Y9,Z9:AD9) -> 0
A10: 6 | B10: =IF(Setting!B24="","",Setting!B24) -> S4 | C10: =IF(B10="","",Setting!C24) -> Transcend | D10: =IF(B10="",0,N(Setting!D24)) -> 480000 | E10: =IF(B10="",0,N(Setting!E24)) -> 2500 | F10: =IF(C10="Conquest",Dashboard!$B$5,IF(C10="Transcend",Dashboard!$B$6,0)) -> 5 | G10: =IF(B10="",0,SUMIFS(Setting!$E$30:$E$39,Setting!$A$30:$A$39,C10,Setting!$C$30:$C$39,"<="&F10,Setting!$D$30:$D$39,">="&F10)) -> 1 | H10: =D10*G10 -> 480000 | I10: =SUMIF($N$17:$N$24,A10,$D$17:$D$24) -> 61 | J10: =IF(B10="",0,SUMIF($C$5:$C$12,C10,$I$5:$I$12)) -> 61 | K10: =IF(B10="",0,SUMIFS(Setting!$E$30:$E$39,Setting!$A$30:$A$39,C10,Setting!$C$30:$C$39,"<="&J10,Setting!$D$30:$D$39,">="&J10)) -> 0.8 | L10: =D10*K10 -> 384000 | M10: =SUMIF($X$17:$X$24,A10,$D$17:$D$24) -> 61 | N10: =IF(B10="",0,SUMPRODUCT(($C$5:$C$12=C10)*(($D$5:$D$12>D10)+($D$5:$D$12=D10)*($A$5:$A$12<A10))*$M$5:$M$12)) -> 0 | O10: =N10+M10 -> 61 | P10: =IF($M10=0,0,MAX(0,MIN($O10-1,AJ10)-MAX($N10,AE10)+1)) -> 56 | Q10: =IF($M10=0,0,MAX(0,MIN($O10-1,AK10)-MAX($N10,AF10)+1)) -> 5 | R10: =IF($M10=0,0,MAX(0,MIN($O10-1,AL10)-MAX($N10,AG10)+1)) -> 0 | S10: =IF($M10=0,0,MAX(0,MIN($O10-1,AM10)-MAX($N10,AH10)+1)) -> 0 | T10: =IF($M10=0,0,MAX(0,MIN($O10-1,AN10)-MAX($N10,AI10)+1)) -> 0 | U10: =IF($M10=0,0,MAX(0,MIN($O10-1,AJ10,$F10-1)-MAX($N10,AE10)+1)) -> 5 | V10: =IF($M10=0,0,MAX(0,MIN($O10-1,AK10,$F10-1)-MAX($N10,AF10)+1)) -> 0 | W10: =IF($M10=0,0,MAX(0,MIN($O10-1,AL10,$F10-1)-MAX($N10,AG10)+1)) -> 0 | X10: =IF($M10=0,0,MAX(0,MIN($O10-1,AM10,$F10-1)-MAX($N10,AH10)+1)) -> 0 | Y10: =IF($M10=0,0,MAX(0,MIN($O10-1,AN10,$F10-1)-MAX($N10,AI10)+1)) -> 0 | Z10: =IF($B10="",0,SUMIFS(Setting!$E$30:$E$39,Setting!$A$30:$A$39,$C10,Setting!$B$30:$B$39,1)) -> 1 | AA10: =IF($B10="",0,SUMIFS(Setting!$E$30:$E$39,Setting!$A$30:$A$39,$C10,Setting!$B$30:$B$39,2)) -> 0.8 | AB10: =IF($B10="",0,SUMIFS(Setting!$E$30:$E$39,Setting!$A$30:$A$39,$C10,Setting!$B$30:$B$39,3)) -> 0.6 | AC10: =IF($B10="",0,SUMIFS(Setting!$E$30:$E$39,Setting!$A$30:$A$39,$C10,Setting!$B$30:$B$39,4)) -> 0.4 | AD10: =IF($B10="",0,SUMIFS(Setting!$E$30:$E$39,Setting!$A$30:$A$39,$C10,Setting!$B$30:$B$39,5)) -> 0.2 | AE10: =IF($B10="",0,SUMIFS(Setting!$C$30:$C$39,Setting!$A$30:$A$39,$C10,Setting!$B$30:$B$39,1)) -> 0 | AF10: =IF($B10="",0,SUMIFS(Setting!$C$30:$C$39,Setting!$A$30:$A$39,$C10,Setting!$B$30:$B$39,2)) -> 56 | AG10: =IF($B10="",0,SUMIFS(Setting!$C$30:$C$39,Setting!$A$30:$A$39,$C10,Setting!$B$30:$B$39,3)) -> 70 | AH10: =IF($B10="",0,SUMIFS(Setting!$C$30:$C$39,Setting!$A$30:$A$39,$C10,Setting!$B$30:$B$39,4)) -> 84 | AI10: =IF($B10="",0,SUMIFS(Setting!$C$30:$C$39,Setting!$A$30:$A$39,$C10,Setting!$B$30:$B$39,5)) -> 98 | AJ10: =IF($B10="",0,SUMIFS(Setting!$D$30:$D$39,Setting!$A$30:$A$39,$C10,Setting!$B$30:$B$39,1)) -> 55 | AK10: =IF($B10="",0,SUMIFS(Setting!$D$30:$D$39,Setting!$A$30:$A$39,$C10,Setting!$B$30:$B$39,2)) -> 69 | AL10: =IF($B10="",0,SUMIFS(Setting!$D$30:$D$39,Setting!$A$30:$A$39,$C10,Setting!$B$30:$B$39,3)) -> 83 | AM10: =IF($B10="",0,SUMIFS(Setting!$D$30:$D$39,Setting!$A$30:$A$39,$C10,Setting!$B$30:$B$39,4)) -> 97 | AN10: =IF($B10="",0,SUMIFS(Setting!$D$30:$D$39,Setting!$A$30:$A$39,$C10,Setting!$B$30:$B$39,5)) -> 999999 | AO10: =$D10*SUMPRODUCT(P10:T10,Z10:AD10) -> 28800000 | AP10: =$D10*SUMPRODUCT(U10:Y10,Z10:AD10) -> 2400000
A11: 7 | B11: =IF(Setting!B25="","",Setting!B25) | C11: =IF(B11="","",Setting!C25) | D11: =IF(B11="",0,N(Setting!D25)) -> 0 | E11: =IF(B11="",0,N(Setting!E25)) -> 0 | F11: =IF(C11="Conquest",Dashboard!$B$5,IF(C11="Transcend",Dashboard!$B$6,0)) -> 0 | G11: =IF(B11="",0,SUMIFS(Setting!$E$30:$E$39,Setting!$A$30:$A$39,C11,Setting!$C$30:$C$39,"<="&F11,Setting!$D$30:$D$39,">="&F11)) -> 0 | H11: =D11*G11 -> 0 | I11: =SUMIF($N$17:$N$24,A11,$D$17:$D$24) -> 0 | J11: =IF(B11="",0,SUMIF($C$5:$C$12,C11,$I$5:$I$12)) -> 0 | K11: =IF(B11="",0,SUMIFS(Setting!$E$30:$E$39,Setting!$A$30:$A$39,C11,Setting!$C$30:$C$39,"<="&J11,Setting!$D$30:$D$39,">="&J11)) -> 0 | L11: =D11*K11 -> 0 | M11: =SUMIF($X$17:$X$24,A11,$D$17:$D$24) -> 0 | N11: =IF(B11="",0,SUMPRODUCT(($C$5:$C$12=C11)*(($D$5:$D$12>D11)+($D$5:$D$12=D11)*($A$5:$A$12<A11))*$M$5:$M$12)) -> 0 | O11: =N11+M11 -> 0 | P11: =IF($M11=0,0,MAX(0,MIN($O11-1,AJ11)-MAX($N11,AE11)+1)) -> 0 | Q11: =IF($M11=0,0,MAX(0,MIN($O11-1,AK11)-MAX($N11,AF11)+1)) -> 0 | R11: =IF($M11=0,0,MAX(0,MIN($O11-1,AL11)-MAX($N11,AG11)+1)) -> 0 | S11: =IF($M11=0,0,MAX(0,MIN($O11-1,AM11)-MAX($N11,AH11)+1)) -> 0 | T11: =IF($M11=0,0,MAX(0,MIN($O11-1,AN11)-MAX($N11,AI11)+1)) -> 0 | U11: =IF($M11=0,0,MAX(0,MIN($O11-1,AJ11,$F11-1)-MAX($N11,AE11)+1)) -> 0 | V11: =IF($M11=0,0,MAX(0,MIN($O11-1,AK11,$F11-1)-MAX($N11,AF11)+1)) -> 0 | W11: =IF($M11=0,0,MAX(0,MIN($O11-1,AL11,$F11-1)-MAX($N11,AG11)+1)) -> 0 | X11: =IF($M11=0,0,MAX(0,MIN($O11-1,AM11,$F11-1)-MAX($N11,AH11)+1)) -> 0 | Y11: =IF($M11=0,0,MAX(0,MIN($O11-1,AN11,$F11-1)-MAX($N11,AI11)+1)) -> 0 | Z11: =IF($B11="",0,SUMIFS(Setting!$E$30:$E$39,Setting!$A$30:$A$39,$C11,Setting!$B$30:$B$39,1)) -> 0 | AA11: =IF($B11="",0,SUMIFS(Setting!$E$30:$E$39,Setting!$A$30:$A$39,$C11,Setting!$B$30:$B$39,2)) -> 0 | AB11: =IF($B11="",0,SUMIFS(Setting!$E$30:$E$39,Setting!$A$30:$A$39,$C11,Setting!$B$30:$B$39,3)) -> 0 | AC11: =IF($B11="",0,SUMIFS(Setting!$E$30:$E$39,Setting!$A$30:$A$39,$C11,Setting!$B$30:$B$39,4)) -> 0 | AD11: =IF($B11="",0,SUMIFS(Setting!$E$30:$E$39,Setting!$A$30:$A$39,$C11,Setting!$B$30:$B$39,5)) -> 0 | AE11: =IF($B11="",0,SUMIFS(Setting!$C$30:$C$39,Setting!$A$30:$A$39,$C11,Setting!$B$30:$B$39,1)) -> 0 | AF11: =IF($B11="",0,SUMIFS(Setting!$C$30:$C$39,Setting!$A$30:$A$39,$C11,Setting!$B$30:$B$39,2)) -> 0 | AG11: =IF($B11="",0,SUMIFS(Setting!$C$30:$C$39,Setting!$A$30:$A$39,$C11,Setting!$B$30:$B$39,3)) -> 0 | AH11: =IF($B11="",0,SUMIFS(Setting!$C$30:$C$39,Setting!$A$30:$A$39,$C11,Setting!$B$30:$B$39,4)) -> 0 | AI11: =IF($B11="",0,SUMIFS(Setting!$C$30:$C$39,Setting!$A$30:$A$39,$C11,Setting!$B$30:$B$39,5)) -> 0 | AJ11: =IF($B11="",0,SUMIFS(Setting!$D$30:$D$39,Setting!$A$30:$A$39,$C11,Setting!$B$30:$B$39,1)) -> 0 | AK11: =IF($B11="",0,SUMIFS(Setting!$D$30:$D$39,Setting!$A$30:$A$39,$C11,Setting!$B$30:$B$39,2)) -> 0 | AL11: =IF($B11="",0,SUMIFS(Setting!$D$30:$D$39,Setting!$A$30:$A$39,$C11,Setting!$B$30:$B$39,3)) -> 0 | AM11: =IF($B11="",0,SUMIFS(Setting!$D$30:$D$39,Setting!$A$30:$A$39,$C11,Setting!$B$30:$B$39,4)) -> 0 | AN11: =IF($B11="",0,SUMIFS(Setting!$D$30:$D$39,Setting!$A$30:$A$39,$C11,Setting!$B$30:$B$39,5)) -> 0 | AO11: =$D11*SUMPRODUCT(P11:T11,Z11:AD11) -> 0 | AP11: =$D11*SUMPRODUCT(U11:Y11,Z11:AD11) -> 0
A12: 8 | B12: =IF(Setting!B26="","",Setting!B26) | C12: =IF(B12="","",Setting!C26) | D12: =IF(B12="",0,N(Setting!D26)) -> 0 | E12: =IF(B12="",0,N(Setting!E26)) -> 0 | F12: =IF(C12="Conquest",Dashboard!$B$5,IF(C12="Transcend",Dashboard!$B$6,0)) -> 0 | G12: =IF(B12="",0,SUMIFS(Setting!$E$30:$E$39,Setting!$A$30:$A$39,C12,Setting!$C$30:$C$39,"<="&F12,Setting!$D$30:$D$39,">="&F12)) -> 0 | H12: =D12*G12 -> 0 | I12: =SUMIF($N$17:$N$24,A12,$D$17:$D$24) -> 0 | J12: =IF(B12="",0,SUMIF($C$5:$C$12,C12,$I$5:$I$12)) -> 0 | K12: =IF(B12="",0,SUMIFS(Setting!$E$30:$E$39,Setting!$A$30:$A$39,C12,Setting!$C$30:$C$39,"<="&J12,Setting!$D$30:$D$39,">="&J12)) -> 0 | L12: =D12*K12 -> 0 | M12: =SUMIF($X$17:$X$24,A12,$D$17:$D$24) -> 0 | N12: =IF(B12="",0,SUMPRODUCT(($C$5:$C$12=C12)*(($D$5:$D$12>D12)+($D$5:$D$12=D12)*($A$5:$A$12<A12))*$M$5:$M$12)) -> 0 | O12: =N12+M12 -> 0 | P12: =IF($M12=0,0,MAX(0,MIN($O12-1,AJ12)-MAX($N12,AE12)+1)) -> 0 | Q12: =IF($M12=0,0,MAX(0,MIN($O12-1,AK12)-MAX($N12,AF12)+1)) -> 0 | R12: =IF($M12=0,0,MAX(0,MIN($O12-1,AL12)-MAX($N12,AG12)+1)) -> 0 | S12: =IF($M12=0,0,MAX(0,MIN($O12-1,AM12)-MAX($N12,AH12)+1)) -> 0 | T12: =IF($M12=0,0,MAX(0,MIN($O12-1,AN12)-MAX($N12,AI12)+1)) -> 0 | U12: =IF($M12=0,0,MAX(0,MIN($O12-1,AJ12,$F12-1)-MAX($N12,AE12)+1)) -> 0 | V12: =IF($M12=0,0,MAX(0,MIN($O12-1,AK12,$F12-1)-MAX($N12,AF12)+1)) -> 0 | W12: =IF($M12=0,0,MAX(0,MIN($O12-1,AL12,$F12-1)-MAX($N12,AG12)+1)) -> 0 | X12: =IF($M12=0,0,MAX(0,MIN($O12-1,AM12,$F12-1)-MAX($N12,AH12)+1)) -> 0 | Y12: =IF($M12=0,0,MAX(0,MIN($O12-1,AN12,$F12-1)-MAX($N12,AI12)+1)) -> 0 | Z12: =IF($B12="",0,SUMIFS(Setting!$E$30:$E$39,Setting!$A$30:$A$39,$C12,Setting!$B$30:$B$39,1)) -> 0 | AA12: =IF($B12="",0,SUMIFS(Setting!$E$30:$E$39,Setting!$A$30:$A$39,$C12,Setting!$B$30:$B$39,2)) -> 0 | AB12: =IF($B12="",0,SUMIFS(Setting!$E$30:$E$39,Setting!$A$30:$A$39,$C12,Setting!$B$30:$B$39,3)) -> 0 | AC12: =IF($B12="",0,SUMIFS(Setting!$E$30:$E$39,Setting!$A$30:$A$39,$C12,Setting!$B$30:$B$39,4)) -> 0 | AD12: =IF($B12="",0,SUMIFS(Setting!$E$30:$E$39,Setting!$A$30:$A$39,$C12,Setting!$B$30:$B$39,5)) -> 0 | AE12: =IF($B12="",0,SUMIFS(Setting!$C$30:$C$39,Setting!$A$30:$A$39,$C12,Setting!$B$30:$B$39,1)) -> 0 | AF12: =IF($B12="",0,SUMIFS(Setting!$C$30:$C$39,Setting!$A$30:$A$39,$C12,Setting!$B$30:$B$39,2)) -> 0 | AG12: =IF($B12="",0,SUMIFS(Setting!$C$30:$C$39,Setting!$A$30:$A$39,$C12,Setting!$B$30:$B$39,3)) -> 0 | AH12: =IF($B12="",0,SUMIFS(Setting!$C$30:$C$39,Setting!$A$30:$A$39,$C12,Setting!$B$30:$B$39,4)) -> 0 | AI12: =IF($B12="",0,SUMIFS(Setting!$C$30:$C$39,Setting!$A$30:$A$39,$C12,Setting!$B$30:$B$39,5)) -> 0 | AJ12: =IF($B12="",0,SUMIFS(Setting!$D$30:$D$39,Setting!$A$30:$A$39,$C12,Setting!$B$30:$B$39,1)) -> 0 | AK12: =IF($B12="",0,SUMIFS(Setting!$D$30:$D$39,Setting!$A$30:$A$39,$C12,Setting!$B$30:$B$39,2)) -> 0 | AL12: =IF($B12="",0,SUMIFS(Setting!$D$30:$D$39,Setting!$A$30:$A$39,$C12,Setting!$B$30:$B$39,3)) -> 0 | AM12: =IF($B12="",0,SUMIFS(Setting!$D$30:$D$39,Setting!$A$30:$A$39,$C12,Setting!$B$30:$B$39,4)) -> 0 | AN12: =IF($B12="",0,SUMIFS(Setting!$D$30:$D$39,Setting!$A$30:$A$39,$C12,Setting!$B$30:$B$39,5)) -> 0 | AO12: =$D12*SUMPRODUCT(P12:T12,Z12:AD12) -> 0 | AP12: =$D12*SUMPRODUCT(U12:Y12,Z12:AD12) -> 0
B13: TOTAL | M13: =SUM(M5:M12) -> 208 | AO13: =SUM(AO5:AO12) -> 65700000 | AP13: =SUM(AP5:AP12) -> 17400000
A16: Karakter | B16: GS | C16: Odyle | D16: Cap cube | E16: V1 m1 | F16: V1 m2 | G16: V1 m3 | H16: V1 m4 | I16: V1 m5 | J16: V1 m6 | K16: V1 m7 | L16: V1 m8 | M16: Best1 | N16: Idx1 | O16: V2 m1 | P16: V2 m2 | Q16: V2 m3 | R16: V2 m4 | S16: V2 m5 | T16: V2 m6 | U16: V2 m7 | V16: V2 m8 | W16: Best2 | X16: Idx2 | Y16: Mode | Z16: Kina/cube skrg | AA16: Skor main | AB16: Rank main | AC16: (kosong) 1 | AD16: (kosong) 2 | AE16: (kosong) 3 | AF16: (kosong) 4 | AG16: (kosong) 5 | AH16: (kosong) 6 | AI16: (kosong) 7 | AJ16: (kosong) 8 | AK16: Best gain/GS | AL16: Idx target | AM16: Target mode | AN16: Target GS | AO16: Kurang GS | AP16: Tambah/cube (info) | AQ16: Tambah/minggu (exact) | AR16: Skor upgrade | AS16: Rank upgrade
A17: =IF(Dashboard!A15="","",Dashboard!A15) -> ChromeT | B17: =IF(OR(A17="",Dashboard!B15=""),0,Dashboard!B15) -> 2531 | C17: =Dashboard!E15 -> Habis | D17: =IF(A17="",0,Setting!E44) -> 61 | E17: =IF(AND($A17<>"",$B17>0,$B$5<>"",$B17>=$E$5),$D$5,0) -> 300000 | F17: =IF(AND($A17<>"",$B17>0,$B$6<>"",$B17>=$E$6),$D$6,0) -> 400000 | G17: =IF(AND($A17<>"",$B17>0,$B$7<>"",$B17>=$E$7),$D$7,0) -> 300000 | H17: =IF(AND($A17<>"",$B17>0,$B$8<>"",$B17>=$E$8),$D$8,0) -> 360000 | I17: =IF(AND($A17<>"",$B17>0,$B$9<>"",$B17>=$E$9),$D$9,0) -> 420000 | J17: =IF(AND($A17<>"",$B17>0,$B$10<>"",$B17>=$E$10),$D$10,0) -> 480000 | K17: =IF(AND($A17<>"",$B17>0,$B$11<>"",$B17>=$E$11),$D$11,0) -> 0 | L17: =IF(AND($A17<>"",$B17>0,$B$12<>"",$B17>=$E$12),$D$12,0) -> 0 | M17: =MAX(E17:L17) -> 480000 | N17: =IF(M17=0,0,MATCH(M17,E17:L17,0)) -> 6 | O17: =IF(E17>0,$L$5,0) -> 60000 | P17: =IF(F17>0,$L$6,0) -> 80000 | Q17: =IF(G17>0,$L$7,0) -> 240000 | R17: =IF(H17>0,$L$8,0) -> 288000 | S17: =IF(I17>0,$L$9,0) -> 336000 | T17: =IF(J17>0,$L$10,0) -> 384000 | U17: =IF(K17>0,$L$11,0) -> 0 | V17: =IF(L17>0,$L$12,0) -> 0 | W17: =MAX(O17:V17) -> 384000 | X17: =IF(W17=0,0,MATCH(W17,O17:V17,0)) -> 6 | Y17: =IF(X17=0,"-",INDEX($B$5:$B$12,X17)) -> S4 | Z17: =IF(X17=0,0,INDEX($H$5:$H$12,X17)) -> 480000 | AA17: =IF(A17="","",IF(AND(C17="Tersedia",X17>0),Z17+(100-ROW())/10000000,-ROW())) -> -17 | AB17: =IF(A17="","",RANK(AA17,$AA$17:$AA$24)) -> 8 | AK17: =MAX(Hitung2!AI20:AI27) -> 0 | AL17: =IF(AK17<=0,0,MATCH(AK17,Hitung2!AI20:AI27,0)) -> 0 | AM17: =IF(AL17=0,"-",INDEX($B$5:$B$12,AL17)) -> - | AN17: =IF(AL17=0,0,INDEX($E$5:$E$12,AL17)) -> 0 | AO17: =IF(AL17=0,0,AN17-B17) -> 0 | AP17: =IF(OR(AL17=0,D17=0),0,AQ17/D17) -> 0 | AQ17: {=IF(AL17=0,0,INDEX(Hitung2!AG20:AG27,AL17))} -> 0 | AR17: =IF(A17="","",IF(AK17>0,AK17+(100-ROW())/1000000,-ROW())) -> -17 | AS17: =IF(A17="","",RANK(AR17,$AR$17:$AR$24)) -> 8
A18: =IF(Dashboard!A16="","",Dashboard!A16) -> Roxarika | B18: =IF(OR(A18="",Dashboard!B16=""),0,Dashboard!B16) -> 1855 | C18: =Dashboard!E16 -> Tersedia | D18: =IF(A18="",0,Setting!E45) -> 21 | E18: =IF(AND($A18<>"",$B18>0,$B$5<>"",$B18>=$E$5),$D$5,0) -> 300000 | F18: =IF(AND($A18<>"",$B18>0,$B$6<>"",$B18>=$E$6),$D$6,0) -> 0 | G18: =IF(AND($A18<>"",$B18>0,$B$7<>"",$B18>=$E$7),$D$7,0) -> 300000 | H18: =IF(AND($A18<>"",$B18>0,$B$8<>"",$B18>=$E$8),$D$8,0) -> 0 | I18: =IF(AND($A18<>"",$B18>0,$B$9<>"",$B18>=$E$9),$D$9,0) -> 0 | J18: =IF(AND($A18<>"",$B18>0,$B$10<>"",$B18>=$E$10),$D$10,0) -> 0 | K18: =IF(AND($A18<>"",$B18>0,$B$11<>"",$B18>=$E$11),$D$11,0) -> 0 | L18: =IF(AND($A18<>"",$B18>0,$B$12<>"",$B18>=$E$12),$D$12,0) -> 0 | M18: =MAX(E18:L18) -> 300000 | N18: =IF(M18=0,0,MATCH(M18,E18:L18,0)) -> 1 | O18: =IF(E18>0,$L$5,0) -> 60000 | P18: =IF(F18>0,$L$6,0) -> 0 | Q18: =IF(G18>0,$L$7,0) -> 240000 | R18: =IF(H18>0,$L$8,0) -> 0 | S18: =IF(I18>0,$L$9,0) -> 0 | T18: =IF(J18>0,$L$10,0) -> 0 | U18: =IF(K18>0,$L$11,0) -> 0 | V18: =IF(L18>0,$L$12,0) -> 0 | W18: =MAX(O18:V18) -> 240000 | X18: =IF(W18=0,0,MATCH(W18,O18:V18,0)) -> 3 | Y18: =IF(X18=0,"-",INDEX($B$5:$B$12,X18)) -> S1 | Z18: =IF(X18=0,0,INDEX($H$5:$H$12,X18)) -> 300000 | AA18: =IF(A18="","",IF(AND(C18="Tersedia",X18>0),Z18+(100-ROW())/10000000,-ROW())) -> 300000 | AB18: =IF(A18="","",RANK(AA18,$AA$17:$AA$24)) -> 1 | AK18: =MAX(Hitung2!AI28:AI35) -> 19200 | AL18: =IF(AK18<=0,0,MATCH(AK18,Hitung2!AI28:AI35,0)) -> 4 | AM18: =IF(AL18=0,"-",INDEX($B$5:$B$12,AL18)) -> S2 | AN18: =IF(AL18=0,0,INDEX($E$5:$E$12,AL18)) -> 1900 | AO18: =IF(AL18=0,0,AN18-B18) -> 45 | AP18: =IF(OR(AL18=0,D18=0),0,AQ18/D18) -> 41142.857 | AQ18: {=IF(AL18=0,0,INDEX(Hitung2!AG28:AG35,AL18))} -> 864000 | AR18: =IF(A18="","",IF(AK18>0,AK18+(100-ROW())/1000000,-ROW())) -> 19200 | AS18: =IF(A18="","",RANK(AR18,$AR$17:$AR$24)) -> 1
A19: =IF(Dashboard!A17="","",Dashboard!A17) -> Crosley | B19: =IF(OR(A19="",Dashboard!B17=""),0,Dashboard!B17) -> 1595 | C19: =Dashboard!E17 -> Tersedia | D19: =IF(A19="",0,Setting!E46) -> 21 | E19: =IF(AND($A19<>"",$B19>0,$B$5<>"",$B19>=$E$5),$D$5,0) -> 300000 | F19: =IF(AND($A19<>"",$B19>0,$B$6<>"",$B19>=$E$6),$D$6,0) -> 0 | G19: =IF(AND($A19<>"",$B19>0,$B$7<>"",$B19>=$E$7),$D$7,0) -> 0 | H19: =IF(AND($A19<>"",$B19>0,$B$8<>"",$B19>=$E$8),$D$8,0) -> 0 | I19: =IF(AND($A19<>"",$B19>0,$B$9<>"",$B19>=$E$9),$D$9,0) -> 0 | J19: =IF(AND($A19<>"",$B19>0,$B$10<>"",$B19>=$E$10),$D$10,0) -> 0 | K19: =IF(AND($A19<>"",$B19>0,$B$11<>"",$B19>=$E$11),$D$11,0) -> 0 | L19: =IF(AND($A19<>"",$B19>0,$B$12<>"",$B19>=$E$12),$D$12,0) -> 0 | M19: =MAX(E19:L19) -> 300000 | N19: =IF(M19=0,0,MATCH(M19,E19:L19,0)) -> 1 | O19: =IF(E19>0,$L$5,0) -> 60000 | P19: =IF(F19>0,$L$6,0) -> 0 | Q19: =IF(G19>0,$L$7,0) -> 0 | R19: =IF(H19>0,$L$8,0) -> 0 | S19: =IF(I19>0,$L$9,0) -> 0 | T19: =IF(J19>0,$L$10,0) -> 0 | U19: =IF(K19>0,$L$11,0) -> 0 | V19: =IF(L19>0,$L$12,0) -> 0 | W19: =MAX(O19:V19) -> 60000 | X19: =IF(W19=0,0,MATCH(W19,O19:V19,0)) -> 1 | Y19: =IF(X19=0,"-",INDEX($B$5:$B$12,X19)) -> T2 | Z19: =IF(X19=0,0,INDEX($H$5:$H$12,X19)) -> 300000 | AA19: =IF(A19="","",IF(AND(C19="Tersedia",X19>0),Z19+(100-ROW())/10000000,-ROW())) -> 300000 | AB19: =IF(A19="","",RANK(AA19,$AA$17:$AA$24)) -> 2 | AK19: =MAX(Hitung2!AI36:AI43) -> 4158.4158 | AL19: =IF(AK19<=0,0,MATCH(AK19,Hitung2!AI36:AI43,0)) -> 2 | AM19: =IF(AL19=0,"-",INDEX($B$5:$B$12,AL19)) -> T3 | AN19: =IF(AL19=0,0,INDEX($E$5:$E$12,AL19)) -> 2100 | AO19: =IF(AL19=0,0,AN19-B19) -> 505 | AP19: =IF(OR(AL19=0,D19=0),0,AQ19/D19) -> 100000 | AQ19: {=IF(AL19=0,0,INDEX(Hitung2!AG36:AG43,AL19))} -> 2100000 | AR19: =IF(A19="","",IF(AK19>0,AK19+(100-ROW())/1000000,-ROW())) -> 4158.4159 | AS19: =IF(A19="","",RANK(AR19,$AR$17:$AR$24)) -> 3
A20: =IF(Dashboard!A18="","",Dashboard!A18) -> Nathanael | B20: =IF(OR(A20="",Dashboard!B18=""),0,Dashboard!B18) -> 1578 | C20: =Dashboard!E18 -> Tersedia | D20: =IF(A20="",0,Setting!E47) -> 21 | E20: =IF(AND($A20<>"",$B20>0,$B$5<>"",$B20>=$E$5),$D$5,0) -> 300000 | F20: =IF(AND($A20<>"",$B20>0,$B$6<>"",$B20>=$E$6),$D$6,0) -> 0 | G20: =IF(AND($A20<>"",$B20>0,$B$7<>"",$B20>=$E$7),$D$7,0) -> 0 | H20: =IF(AND($A20<>"",$B20>0,$B$8<>"",$B20>=$E$8),$D$8,0) -> 0 | I20: =IF(AND($A20<>"",$B20>0,$B$9<>"",$B20>=$E$9),$D$9,0) -> 0 | J20: =IF(AND($A20<>"",$B20>0,$B$10<>"",$B20>=$E$10),$D$10,0) -> 0 | K20: =IF(AND($A20<>"",$B20>0,$B$11<>"",$B20>=$E$11),$D$11,0) -> 0 | L20: =IF(AND($A20<>"",$B20>0,$B$12<>"",$B20>=$E$12),$D$12,0) -> 0 | M20: =MAX(E20:L20) -> 300000 | N20: =IF(M20=0,0,MATCH(M20,E20:L20,0)) -> 1 | O20: =IF(E20>0,$L$5,0) -> 60000 | P20: =IF(F20>0,$L$6,0) -> 0 | Q20: =IF(G20>0,$L$7,0) -> 0 | R20: =IF(H20>0,$L$8,0) -> 0 | S20: =IF(I20>0,$L$9,0) -> 0 | T20: =IF(J20>0,$L$10,0) -> 0 | U20: =IF(K20>0,$L$11,0) -> 0 | V20: =IF(L20>0,$L$12,0) -> 0 | W20: =MAX(O20:V20) -> 60000 | X20: =IF(W20=0,0,MATCH(W20,O20:V20,0)) -> 1 | Y20: =IF(X20=0,"-",INDEX($B$5:$B$12,X20)) -> T2 | Z20: =IF(X20=0,0,INDEX($H$5:$H$12,X20)) -> 300000 | AA20: =IF(A20="","",IF(AND(C20="Tersedia",X20>0),Z20+(100-ROW())/10000000,-ROW())) -> 300000 | AB20: =IF(A20="","",RANK(AA20,$AA$17:$AA$24)) -> 3 | AK20: =MAX(Hitung2!AI44:AI51) -> 4022.9885 | AL20: =IF(AK20<=0,0,MATCH(AK20,Hitung2!AI44:AI51,0)) -> 2 | AM20: =IF(AL20=0,"-",INDEX($B$5:$B$12,AL20)) -> T3 | AN20: =IF(AL20=0,0,INDEX($E$5:$E$12,AL20)) -> 2100 | AO20: =IF(AL20=0,0,AN20-B20) -> 522 | AP20: =IF(OR(AL20=0,D20=0),0,AQ20/D20) -> 100000 | AQ20: {=IF(AL20=0,0,INDEX(Hitung2!AG44:AG51,AL20))} -> 2100000 | AR20: =IF(A20="","",IF(AK20>0,AK20+(100-ROW())/1000000,-ROW())) -> 4022.9886 | AS20: =IF(A20="","",RANK(AR20,$AR$17:$AR$24)) -> 5
A21: =IF(Dashboard!A19="","",Dashboard!A19) -> Cicero | B21: =IF(OR(A21="",Dashboard!B19=""),0,Dashboard!B19) -> 1502 | C21: =Dashboard!E19 -> Tersedia | D21: =IF(A21="",0,Setting!E48) -> 21 | E21: =IF(AND($A21<>"",$B21>0,$B$5<>"",$B21>=$E$5),$D$5,0) -> 300000 | F21: =IF(AND($A21<>"",$B21>0,$B$6<>"",$B21>=$E$6),$D$6,0) -> 0 | G21: =IF(AND($A21<>"",$B21>0,$B$7<>"",$B21>=$E$7),$D$7,0) -> 0 | H21: =IF(AND($A21<>"",$B21>0,$B$8<>"",$B21>=$E$8),$D$8,0) -> 0 | I21: =IF(AND($A21<>"",$B21>0,$B$9<>"",$B21>=$E$9),$D$9,0) -> 0 | J21: =IF(AND($A21<>"",$B21>0,$B$10<>"",$B21>=$E$10),$D$10,0) -> 0 | K21: =IF(AND($A21<>"",$B21>0,$B$11<>"",$B21>=$E$11),$D$11,0) -> 0 | L21: =IF(AND($A21<>"",$B21>0,$B$12<>"",$B21>=$E$12),$D$12,0) -> 0 | M21: =MAX(E21:L21) -> 300000 | N21: =IF(M21=0,0,MATCH(M21,E21:L21,0)) -> 1 | O21: =IF(E21>0,$L$5,0) -> 60000 | P21: =IF(F21>0,$L$6,0) -> 0 | Q21: =IF(G21>0,$L$7,0) -> 0 | R21: =IF(H21>0,$L$8,0) -> 0 | S21: =IF(I21>0,$L$9,0) -> 0 | T21: =IF(J21>0,$L$10,0) -> 0 | U21: =IF(K21>0,$L$11,0) -> 0 | V21: =IF(L21>0,$L$12,0) -> 0 | W21: =MAX(O21:V21) -> 60000 | X21: =IF(W21=0,0,MATCH(W21,O21:V21,0)) -> 1 | Y21: =IF(X21=0,"-",INDEX($B$5:$B$12,X21)) -> T2 | Z21: =IF(X21=0,0,INDEX($H$5:$H$12,X21)) -> 300000 | AA21: =IF(A21="","",IF(AND(C21="Tersedia",X21>0),Z21+(100-ROW())/10000000,-ROW())) -> 300000 | AB21: =IF(A21="","",RANK(AA21,$AA$17:$AA$24)) -> 4 | AK21: =MAX(Hitung2!AI52:AI59) -> 3511.7057 | AL21: =IF(AK21<=0,0,MATCH(AK21,Hitung2!AI52:AI59,0)) -> 2 | AM21: =IF(AL21=0,"-",INDEX($B$5:$B$12,AL21)) -> T3 | AN21: =IF(AL21=0,0,INDEX($E$5:$E$12,AL21)) -> 2100 | AO21: =IF(AL21=0,0,AN21-B21) -> 598 | AP21: =IF(OR(AL21=0,D21=0),0,AQ21/D21) -> 100000 | AQ21: {=IF(AL21=0,0,INDEX(Hitung2!AG52:AG59,AL21))} -> 2100000 | AR21: =IF(A21="","",IF(AK21>0,AK21+(100-ROW())/1000000,-ROW())) -> 3511.7058 | AS21: =IF(A21="","",RANK(AR21,$AR$17:$AR$24)) -> 7
A22: =IF(Dashboard!A20="","",Dashboard!A20) -> Seneca | B22: =IF(OR(A22="",Dashboard!B20=""),0,Dashboard!B20) -> 1604 | C22: =Dashboard!E20 -> Tersedia | D22: =IF(A22="",0,Setting!E49) -> 21 | E22: =IF(AND($A22<>"",$B22>0,$B$5<>"",$B22>=$E$5),$D$5,0) -> 300000 | F22: =IF(AND($A22<>"",$B22>0,$B$6<>"",$B22>=$E$6),$D$6,0) -> 0 | G22: =IF(AND($A22<>"",$B22>0,$B$7<>"",$B22>=$E$7),$D$7,0) -> 300000 | H22: =IF(AND($A22<>"",$B22>0,$B$8<>"",$B22>=$E$8),$D$8,0) -> 0 | I22: =IF(AND($A22<>"",$B22>0,$B$9<>"",$B22>=$E$9),$D$9,0) -> 0 | J22: =IF(AND($A22<>"",$B22>0,$B$10<>"",$B22>=$E$10),$D$10,0) -> 0 | K22: =IF(AND($A22<>"",$B22>0,$B$11<>"",$B22>=$E$11),$D$11,0) -> 0 | L22: =IF(AND($A22<>"",$B22>0,$B$12<>"",$B22>=$E$12),$D$12,0) -> 0 | M22: =MAX(E22:L22) -> 300000 | N22: =IF(M22=0,0,MATCH(M22,E22:L22,0)) -> 1 | O22: =IF(E22>0,$L$5,0) -> 60000 | P22: =IF(F22>0,$L$6,0) -> 0 | Q22: =IF(G22>0,$L$7,0) -> 240000 | R22: =IF(H22>0,$L$8,0) -> 0 | S22: =IF(I22>0,$L$9,0) -> 0 | T22: =IF(J22>0,$L$10,0) -> 0 | U22: =IF(K22>0,$L$11,0) -> 0 | V22: =IF(L22>0,$L$12,0) -> 0 | W22: =MAX(O22:V22) -> 240000 | X22: =IF(W22=0,0,MATCH(W22,O22:V22,0)) -> 3 | Y22: =IF(X22=0,"-",INDEX($B$5:$B$12,X22)) -> S1 | Z22: =IF(X22=0,0,INDEX($H$5:$H$12,X22)) -> 300000 | AA22: =IF(A22="","",IF(AND(C22="Tersedia",X22>0),Z22+(100-ROW())/10000000,-ROW())) -> 300000 | AB22: =IF(A22="","",RANK(AA22,$AA$17:$AA$24)) -> 5 | AK22: =MAX(Hitung2!AI60:AI67) -> 7137.0968 | AL22: =IF(AK22<=0,0,MATCH(AK22,Hitung2!AI60:AI67,0)) -> 2 | AM22: =IF(AL22=0,"-",INDEX($B$5:$B$12,AL22)) -> T3 | AN22: =IF(AL22=0,0,INDEX($E$5:$E$12,AL22)) -> 2100 | AO22: =IF(AL22=0,0,AN22-B22) -> 496 | AP22: =IF(OR(AL22=0,D22=0),0,AQ22/D22) -> 168571.43 | AQ22: {=IF(AL22=0,0,INDEX(Hitung2!AG60:AG67,AL22))} -> 3540000 | AR22: =IF(A22="","",IF(AK22>0,AK22+(100-ROW())/1000000,-ROW())) -> 7137.0969 | AS22: =IF(A22="","",RANK(AR22,$AR$17:$AR$24)) -> 2
A23: =IF(Dashboard!A21="","",Dashboard!A21) -> Averroes | B23: =IF(OR(A23="",Dashboard!B21=""),0,Dashboard!B21) -> 1595 | C23: =Dashboard!E21 -> Tersedia | D23: =IF(A23="",0,Setting!E50) -> 21 | E23: =IF(AND($A23<>"",$B23>0,$B$5<>"",$B23>=$E$5),$D$5,0) -> 300000 | F23: =IF(AND($A23<>"",$B23>0,$B$6<>"",$B23>=$E$6),$D$6,0) -> 0 | G23: =IF(AND($A23<>"",$B23>0,$B$7<>"",$B23>=$E$7),$D$7,0) -> 0 | H23: =IF(AND($A23<>"",$B23>0,$B$8<>"",$B23>=$E$8),$D$8,0) -> 0 | I23: =IF(AND($A23<>"",$B23>0,$B$9<>"",$B23>=$E$9),$D$9,0) -> 0 | J23: =IF(AND($A23<>"",$B23>0,$B$10<>"",$B23>=$E$10),$D$10,0) -> 0 | K23: =IF(AND($A23<>"",$B23>0,$B$11<>"",$B23>=$E$11),$D$11,0) -> 0 | L23: =IF(AND($A23<>"",$B23>0,$B$12<>"",$B23>=$E$12),$D$12,0) -> 0 | M23: =MAX(E23:L23) -> 300000 | N23: =IF(M23=0,0,MATCH(M23,E23:L23,0)) -> 1 | O23: =IF(E23>0,$L$5,0) -> 60000 | P23: =IF(F23>0,$L$6,0) -> 0 | Q23: =IF(G23>0,$L$7,0) -> 0 | R23: =IF(H23>0,$L$8,0) -> 0 | S23: =IF(I23>0,$L$9,0) -> 0 | T23: =IF(J23>0,$L$10,0) -> 0 | U23: =IF(K23>0,$L$11,0) -> 0 | V23: =IF(L23>0,$L$12,0) -> 0 | W23: =MAX(O23:V23) -> 60000 | X23: =IF(W23=0,0,MATCH(W23,O23:V23,0)) -> 1 | Y23: =IF(X23=0,"-",INDEX($B$5:$B$12,X23)) -> T2 | Z23: =IF(X23=0,0,INDEX($H$5:$H$12,X23)) -> 300000 | AA23: =IF(A23="","",IF(AND(C23="Tersedia",X23>0),Z23+(100-ROW())/10000000,-ROW())) -> 300000 | AB23: =IF(A23="","",RANK(AA23,$AA$17:$AA$24)) -> 6 | AK23: =MAX(Hitung2!AI68:AI75) -> 4158.4158 | AL23: =IF(AK23<=0,0,MATCH(AK23,Hitung2!AI68:AI75,0)) -> 2 | AM23: =IF(AL23=0,"-",INDEX($B$5:$B$12,AL23)) -> T3 | AN23: =IF(AL23=0,0,INDEX($E$5:$E$12,AL23)) -> 2100 | AO23: =IF(AL23=0,0,AN23-B23) -> 505 | AP23: =IF(OR(AL23=0,D23=0),0,AQ23/D23) -> 100000 | AQ23: {=IF(AL23=0,0,INDEX(Hitung2!AG68:AG75,AL23))} -> 2100000 | AR23: =IF(A23="","",IF(AK23>0,AK23+(100-ROW())/1000000,-ROW())) -> 4158.4159 | AS23: =IF(A23="","",RANK(AR23,$AR$17:$AR$24)) -> 4
